Workbook
Name LOCKERT: #REF!
Name PERSONAL: PERSONAL!$J$2:$J$81
Name Area: PERSONAL!$L$2:$L$14
Name Talla: PERSONAL!$M$2:$M$7
Name DOTACION: DOTACIONES!$H:$H
Name AreadeLockers: #REF!

Sheet ASIGNACIONES
A1: ID asignaciones | B1: Codigo de Dotacion | C1: Fecha de Entrega | D1: Operario | E1: Codigo de Lockets | F1: identificacion | G1: Area | H1: Talla de Operarios | I1: Talla de dotacion asignada | J1: Area de Lockers | K1: Observaciones | L1: Imagen
F2: {=IFERROR(VLOOKUP($D2:$D991,PERSONAL!B:E,2,0),"")} | G2: {=IFERROR(VLOOKUP($D2:$D991,PERSONAL!B:F,3,0),"")} | H2: {=IFERROR(VLOOKUP($D2:$D991,PERSONAL!$B:$E,4,0),"")} | I2: {=IFERROR(VLOOKUP($B2:B991,DOTACIONES!$B:$E,3,0),"")} | J2: {=IFERROR(VLOOKUP($D2:$D991,PERSONAL!B:F,5,0),"")}
A5: 7c03cf97 | B5: 030 | C5: 45129 | D5: AMAYA TASCO JORGE ALEXIS | E5: DES-05 | F5: 1095917149 | G5: DES | H5: M | I5: M | J5: VESTIDOR HOMBRES
A6: 468a8616 | B6: 028 | C6: 45129 | D6: ANGARITA CASTILLO HERSON DAVID | E6: DES-11 | F6: 1095909192 | G6: DES | H6: L | I6: L | J6: VESTIDOR HOMBRES
A8: 00ee1a64 | B8: 052 | C8: 45129 | D8: ARDILA PARRA JOAO CARLOS | E8: DES-07 | F8: 91540171 | G8: DES | H8: L | I8: L | J8: VESTIDOR HOMBRES
A9: 07fbd56b | B9: 021 | C9: 45129 | D9: CARRILLO SUAREZ YEINSS | E9: DES-33 | F9: 91541543 | G9: DES | H9: L | I9: L | J9: VESTIDOR HOMBRES
A11: 17dd008b | B11: 014 | C11: 45129 | D11: DELGADO GARCIA CESAR YESSY | E11: DES-17 | F11: 1102726333 | G11: DES | H11: XXL | I11: XXL | J11: VESTIDOR HOMBRES
A12: 5b402578 | B12: 009 | C12: 45129 | D12: DIAZ PABON ERWIN | E12: DES-23 | F12: 1098604376 | G12: DES | H12: M | I12: L | J12: VESTIDOR HOMBRES
A14: 7f0f5f4d | B14: 017 | C14: 45129 | D14: GAMBOA ANGARITA HOSLTMAN ARLEY | E14: DES-31 | F14: 1004966700 | G14: DES | H14: XXL | I14: XXL | J14: VESTIDOR HOMBRES
A15: ff826fb2 | B15: 007 | C15: 45129 | D15: GONZALEZ DELGADO EDUAR VIRLEY | E15: DES-13 | F15: 91301967 | G15: DES | H15: L | I15: L | J15: VESTIDOR HOMBRES
A17: 99e9b745 | B17: 038 | C17: 45129 | D17: JAIMES ESPITIA DIEGO ARMANDO | E17: DES-34 | F17: 1102360952 | G17: DES | H17: L | I17: L | J17: VESTIDOR HOMBRES
A18: d6d2f707 | B18: 106 | C18: 45129 | D18: MANTENIMIENTO 1 | E18: MTTO-01 | F18: 123456 | G18: MTTO | H18: M | I18: M | J18: VESTIDOR HOMBRES
A19: ef171cef | B19: 107 | C19: 45129 | D19: MANTENIMIENTO 2 | E19: MTTO-02 | F19: 123456 | G19: MTTO | H19: L | I19: L | J19: VESTIDOR HOMBRES
A20: f8fa1cbb | B20: 036 | C20: 45129 | D20: MENDEZ BRAN HECTOR GERARDO | E20: DES-12 | F20: 1100893469 | G20: DES | H20: XL | I20: XL | J20: VESTIDOR HOMBRES
... A69: 6c5f9876 | B69: 125 | C69: 45895 | D69: HIGUERA JAIMES ADRIANA LICETH | E69: CAL-03 | F69: 1005449575 | G69: CAL | H69: XS | I69: XS | J69: VESTIDOR MUJERES

Sheet LOCKERES
A1: Area | B1: Codigo de Lockets | C1: Area de Lockers | D1: ESTADO | E1: UNIDAD
A2: DES | B2: DES-01 | C2: VESTIDOR HOMBRES | D2: =IF(A2="VIS","LOCKERT VISITA",IF(COUNTIFS(ASIGNACIONES!E:E,B2,ASIGNACIONES!G:G,A2,ASIGNACIONES!J:J,C2)=0,"LOCKERT DISPONIBLE","LOCKERT ASIGNADO")) -> LOCKERT ASIGNADO | E2: 1
A3: DES | B3: DES-02 | C3: VESTIDOR HOMBRES | D3: =IF(A3="VIS","LOCKERT VISITA",IF(COUNTIFS(ASIGNACIONES!E:E,B3,ASIGNACIONES!G:G,A3,ASIGNACIONES!J:J,C3)=0,"LOCKERT DISPONIBLE","LOCKERT ASIGNADO")) -> LOCKERT ASIGNADO | E3: 1
A4: DES | B4: DES-03 | C4: VESTIDOR HOMBRES | D4: =IF(A4="VIS","LOCKERT VISITA",IF(COUNTIFS(ASIGNACIONES!E:E,B4,ASIGNACIONES!G:G,A4,ASIGNACIONES!J:J,C4)=0,"LOCKERT DISPONIBLE","LOCKERT ASIGNADO")) -> LOCKERT ASIGNADO | E4: 1
A5: DES | B5: DES-04 | C5: VESTIDOR HOMBRES | D5: =IF(A5="VIS","LOCKERT VISITA",IF(COUNTIFS(ASIGNACIONES!E:E,B5,ASIGNACIONES!G:G,A5,ASIGNACIONES!J:J,C5)=0,"LOCKERT DISPONIBLE","LOCKERT ASIGNADO")) -> LOCKERT DISPONIBLE | E5: 1
A6: DES | B6: DES-05 | C6: VESTIDOR HOMBRES | D6: =IF(A6="VIS","LOCKERT VISITA",IF(COUNTIFS(ASIGNACIONES!E:E,B6,ASIGNACIONES!G:G,A6,ASIGNACIONES!J:J,C6)=0,"LOCKERT DISPONIBLE","LOCKERT ASIGNADO")) -> LOCKERT ASIGNADO | E6: 1
A7: DES | B7: DES-06 | C7: VESTIDOR HOMBRES | D7: =IF(A7="VIS","LOCKERT VISITA",IF(COUNTIFS(ASIGNACIONES!E:E,B7,ASIGNACIONES!G:G,A7,ASIGNACIONES!J:J,C7)=0,"LOCKERT DISPONIBLE","LOCKERT ASIGNADO")) -> LOCKERT ASIGNADO | E7: 1
A8: DES | B8: DES-07 | C8: VESTIDOR HOMBRES | D8: =IF(A8="VIS","LOCKERT VISITA",IF(COUNTIFS(ASIGNACIONES!E:E,B8,ASIGNACIONES!G:G,A8,ASIGNACIONES!J:J,C8)=0,"LOCKERT DISPONIBLE","LOCKERT ASIGNADO")) -> LOCKERT ASIGNADO | E8: 1
A9: DES | B9: DES-08 | C9: VESTIDOR HOMBRES | D9: =IF(A9="VIS","LOCKERT VISITA",IF(COUNTIFS(ASIGNACIONES!E:E,B9,ASIGNACIONES!G:G,A9,ASIGNACIONES!J:J,C9)=0,"LOCKERT DISPONIBLE","LOCKERT ASIGNADO")) -> LOCKERT DISPONIBLE | E9: 1
A10: DES | B10: DES-09 | C10: VESTIDOR HOMBRES | D10: =IF(A10="VIS","LOCKERT VISITA",IF(COUNTIFS(ASIGNACIONES!E:E,B10,ASIGNACIONES!G:G,A10,ASIGNACIONES!J:J,C10)=0,"LOCKERT DISPONIBLE","LOCKERT ASIGNADO")) -> LOCKERT DISPONIBLE | E10: 1
A11: DES | B11: DES-10 | C11: VESTIDOR HOMBRES | D11: =IF(A11="VIS","LOCKERT VISITA",IF(COUNTIFS(ASIGNACIONES!E:E,B11,ASIGNACIONES!G:G,A11,ASIGNACIONES!J:J,C11)=0,"LOCKERT DISPONIBLE","LOCKERT ASIGNADO")) -> LOCKERT DISPONIBLE | E11: 1
A12: DES | B12: DES-11 | C12: VESTIDOR HOMBRES | D12: =IF(A12="VIS","LOCKERT VISITA",IF(COUNTIFS(ASIGNACIONES!E:E,B12,ASIGNACIONES!G:G,A12,ASIGNACIONES!J:J,C12)=0,"LOCKERT DISPONIBLE","LOCKERT ASIGNADO")) -> LOCKERT ASIGNADO | E12: 1
A13: DES | B13: DES-12 | C13: VESTIDOR HOMBRES | D13: =IF(A13="VIS","LOCKERT VISITA",IF(COUNTIFS(ASIGNACIONES!E:E,B13,ASIGNACIONES!G:G,A13,ASIGNACIONES!J:J,C13)=0,"LOCKERT DISPONIBLE","LOCKERT ASIGNADO")) -> LOCKERT ASIGNADO | E13: 1
... A64: CAL | B64: CAL-05 | C64: ADMINISTRACION | D64: =IF(A64="VIS","LOCKERT VISITA",IF(COUNTIFS(ASIGNACIONES!E:E,B64,ASIGNACIONES!G:G,A64,ASIGNACIONES!J:J,C64)=0,"LOCKERT DISPONIBLE","LOCKERT ASIGNADO")) -> LOCKERT DISPONIBLE | E64: 1

Sheet PERSONAL
A1: ID PERSONAL | B1: Operario | C1: identificacion | D1: Area | E1: Talla | F1: Area de Lockers | G1: IMAGEN | H1: estado
A4: HK155JJ8 | B4: AMAYA TASCO JORGE ALEXIS | C4: 1095917149 | D4: DES | E4: M | F4: VESTIDOR HOMBRES | H4: =IF($B4="","",IF($B4="TRANSCARNES","ACTIVO",IF(COUNTIF(RETIROS!E:E,$B4)=1,"PENDIENTE ELIMINAR",IF(COUNTIFS(ASIGNACIONES!$D:$D,$B4,ASIGNACIONES!$H:$H,E4,ASIGNACIONES!$G:$G,$D4,ASIGNACIONES!$J:$J,$F4)=0,"NUEVO","ACTIVO")))) -> ACTIVO
A5: HK155JJ10 | B5: ANGARITA CASTILLO HERSON DAVID | C5: 1095909192 | D5: DES | E5: L | F5: VESTIDOR HOMBRES | H5: =IF($B5="","",IF($B5="TRANSCARNES","ACTIVO",IF(COUNTIF(RETIROS!E:E,$B5)=1,"PENDIENTE ELIMINAR",IF(COUNTIFS(ASIGNACIONES!$D:$D,$B5,ASIGNACIONES!$H:$H,E5,ASIGNACIONES!$G:$G,$D5,ASIGNACIONES!$J:$J,$F5)=0,"NUEVO","ACTIVO")))) -> ACTIVO
A7: HK155JJ13 | B7: ARDILA PARRA JOAO CARLOS | C7: 91540171 | D7: DES | E7: L | F7: VESTIDOR HOMBRES | H7: =IF($B7="","",IF($B7="TRANSCARNES","ACTIVO",IF(COUNTIF(RETIROS!E:E,$B7)=1,"PENDIENTE ELIMINAR",IF(COUNTIFS(ASIGNACIONES!$D:$D,$B7,ASIGNACIONES!$H:$H,E7,ASIGNACIONES!$G:$G,$D7,ASIGNACIONES!$J:$J,$F7)=0,"NUEVO","ACTIVO")))) -> ACTIVO
A9: HK155JJ15 | B9: CARRILLO SUAREZ YEINSS | C9: 91541543 | D9: DES | E9: L | F9: VESTIDOR HOMBRES | H9: =IF($B9="","",IF($B9="TRANSCARNES","ACTIVO",IF(COUNTIF(RETIROS!E:E,$B9)=1,"PENDIENTE ELIMINAR",IF(COUNTIFS(ASIGNACIONES!$D:$D,$B9,ASIGNACIONES!$H:$H,E9,ASIGNACIONES!$G:$G,$D9,ASIGNACIONES!$J:$J,$F9)=0,"NUEVO","ACTIVO")))) -> ACTIVO
A11: HK155JJ18 | B11: DELGADO GARCIA CESAR YESSY | C11: 1102726333 | D11: DES | E11: XXL | F11: VESTIDOR HOMBRES | H11: =IF($B11="","",IF($B11="TRANSCARNES","ACTIVO",IF(COUNTIF(RETIROS!E:E,$B11)=1,"PENDIENTE ELIMINAR",IF(COUNTIFS(ASIGNACIONES!$D:$D,$B11,ASIGNACIONES!$H:$H,E11,ASIGNACIONES!$G:$G,$D11,ASIGNACIONES!$J:$J,$F11)=0,"NUEVO","ACTIVO")))) -> ACTIVO
A12: HK155JJ19 | B12: DIAZ PABON ERWIN | C12: 1098604376 | D12: DES | E12: M | F12: VESTIDOR HOMBRES | H12: =IF($B12="","",IF($B12="TRANSCARNES","ACTIVO",IF(COUNTIF(RETIROS!E:E,$B12)=1,"PENDIENTE ELIMINAR",IF(COUNTIFS(ASIGNACIONES!$D:$D,$B12,ASIGNACIONES!$H:$H,E12,ASIGNACIONES!$G:$G,$D12,ASIGNACIONES!$J:$J,$F12)=0,"NUEVO","ACTIVO")))) -> ACTIVO
A15: HK155JJ21 | B15: GAMBOA ANGARITA HOSLTMAN ARLEY | C15: 1004966700 | D15: DES | E15: XXL | F15: VESTIDOR HOMBRES | H15: =IF($B15="","",IF($B15="TRANSCARNES","ACTIVO",IF(COUNTIF(RETIROS!E:E,$B15)=1,"PENDIENTE ELIMINAR",IF(COUNTIFS(ASIGNACIONES!$D:$D,$B15,ASIGNACIONES!$H:$H,E15,ASIGNACIONES!$G:$G,$D15,ASIGNACIONES!$J:$J,$F15)=0,"NUEVO","ACTIVO")))) -> ACTIVO
A16: HK155JJ22 | B16: GONZALEZ DELGADO EDUAR VIRLEY | C16: 91301967 | D16: DES | E16: L | F16: VESTIDOR HOMBRES | H16: =IF($B16="","",IF($B16="TRANSCARNES","ACTIVO",IF(COUNTIF(RETIROS!E:E,$B16)=1,"PENDIENTE ELIMINAR",IF(COUNTIFS(ASIGNACIONES!$D:$D,$B16,ASIGNACIONES!$H:$H,E16,ASIGNACIONES!$G:$G,$D16,ASIGNACIONES!$J:$J,$F16)=0,"NUEVO","ACTIVO")))) -> ACTIVO
A20: HK155JJ26 | B20: JAIMES ESPITIA DIEGO ARMANDO | C20: 1102360952 | D20: DES | E20: L | F20: VESTIDOR HOMBRES | H20: =IF($B20="","",IF($B20="TRANSCARNES","ACTIVO",IF(COUNTIF(RETIROS!E:E,$B20)=1,"PENDIENTE ELIMINAR",IF(COUNTIFS(ASIGNACIONES!$D:$D,$B20,ASIGNACIONES!$H:$H,E20,ASIGNACIONES!$G:$G,$D20,ASIGNACIONES!$J:$J,$F20)=0,"NUEVO","ACTIVO")))) -> ACTIVO
A22: HK155JJ46 | B22: MANTENIMIENTO 1 | C22: 123456 | D22: MTTO | E22: M | F22: VESTIDOR HOMBRES | H22: =IF($B22="","",IF($B22="TRANSCARNES","ACTIVO",IF(COUNTIF(RETIROS!E:E,$B22)=1,"PENDIENTE ELIMINAR",IF(COUNTIFS(ASIGNACIONES!$D:$D,$B22,ASIGNACIONES!$H:$H,E22,ASIGNACIONES!$G:$G,$D22,ASIGNACIONES!$J:$J,$F22)=0,"NUEVO","ACTIVO")))) -> ACTIVO
A23: HK155JJ47 | B23: MANTENIMIENTO 2 | C23: 123456 | D23: MTTO | E23: L | F23: VESTIDOR HOMBRES | H23: =IF($B23="","",IF($B23="TRANSCARNES","ACTIVO",IF(COUNTIF(RETIROS!E:E,$B23)=1,"PENDIENTE ELIMINAR",IF(COUNTIFS(ASIGNACIONES!$D:$D,$B23,ASIGNACIONES!$H:$H,E23,ASIGNACIONES!$G:$G,$D23,ASIGNACIONES!$J:$J,$F23)=0,"NUEVO","ACTIVO")))) -> ACTIVO
A25: HK155JJ29 | B25: MENDEZ BRAN HECTOR GERARDO | C25: 1100893469 | D25: DES | E25: XL | F25: VESTIDOR HOMBRES | H25: =IF($B25="","",IF($B25="TRANSCARNES","ACTIVO",IF(COUNTIF(RETIROS!E:E,$B25)=1,"PENDIENTE ELIMINAR",IF(COUNTIFS(ASIGNACIONES!$D:$D,$B25,ASIGNACIONES!$H:$H,E25,ASIGNACIONES!$G:$G,$D25,ASIGNACIONES!$J:$J,$F25)=0,"NUEVO","ACTIVO")))) -> ACTIVO
... A71: 8cad9b74 | B71: FIGUEREDO SANMILLAN ALEXANDER | C71: 1099362991 | D71: DES | E71: L | F71: VESTIDOR HOMBRES | H71: =IF($B71="","",IF($B71="TRANSCARNES","ACTIVO",IF(COUNTIF(RETIROS!E:E,$B71)=1,"PENDIENTE ELIMINAR",IF(COUNTIFS(ASIGNACIONES!$D:$D,$B71,ASIGNACIONES!$H:$H,E71,ASIGNACIONES!$G:$G,$D71,ASIGNACIONES!$J:$J,$F71)=0,"NUEVO","ACTIVO")))) -> NUEVO
H73: =IF($B73="","",IF($B73="TRANSCARNES","ACTIVO",IF(COUNTIF(RETIROS!E:E,$B73)=1,"PENDIENTE ELIMINAR",IF(COUNTIFS(ASIGNACIONES!$D:$D,$B73,ASIGNACIONES!$H:$H,E73,ASIGNACIONES!$G:$G,$D73,ASIGNACIONES!$J:$J,$F73)=0,"NUEVO","ACTIVO"))))
H74: =IF($B74="","",IF($B74="TRANSCARNES","ACTIVO",IF(COUNTIF(RETIROS!E:E,$B74)=1,"PENDIENTE ELIMINAR",IF(COUNTIFS(ASIGNACIONES!$D:$D,$B74,ASIGNACIONES!$H:$H,E74,ASIGNACIONES!$G:$G,$D74,ASIGNACIONES!$J:$J,$F74)=0,"NUEVO","ACTIVO"))))
H75: =IF($B75="","",IF($B75="TRANSCARNES","ACTIVO",IF(COUNTIF(RETIROS!E:E,$B75)=1,"PENDIENTE ELIMINAR",IF(COUNTIFS(ASIGNACIONES!$D:$D,$B75,ASIGNACIONES!$H:$H,E75,ASIGNACIONES!$G:$G,$D75,ASIGNACIONES!$J:$J,$F75)=0,"NUEVO","ACTIVO"))))
H76: =IF($B76="","",IF($B76="TRANSCARNES","ACTIVO",IF(COUNTIF(RETIROS!E:E,$B76)=1,"PENDIENTE ELIMINAR",IF(COUNTIFS(ASIGNACIONES!$D:$D,$B76,ASIGNACIONES!$H:$H,E76,ASIGNACIONES!$G:$G,$D76,ASIGNACIONES!$J:$J,$F76)=0,"NUEVO","ACTIVO"))))
H77: =IF($B77="","",IF($B77="TRANSCARNES","ACTIVO",IF(COUNTIF(RETIROS!E:E,$B77)=1,"PENDIENTE ELIMINAR",IF(COUNTIFS(ASIGNACIONES!$D:$D,$B77,ASIGNACIONES!$H:$H,E77,ASIGNACIONES!$G:$G,$D77,ASIGNACIONES!$J:$J,$F77)=0,"NUEVO","ACTIVO"))))
H78: =IF($B78="","",IF($B78="TRANSCARNES","ACTIVO",IF(COUNTIF(RETIROS!E:E,$B78)=1,"PENDIENTE ELIMINAR",IF(COUNTIFS(ASIGNACIONES!$D:$D,$B78,ASIGNACIONES!$H:$H,E78,ASIGNACIONES!$G:$G,$D78,ASIGNACIONES!$J:$J,$F78)=0,"NUEVO","ACTIVO"))))
H79: =IF($B79="","",IF($B79="TRANSCARNES","ACTIVO",IF(COUNTIF(RETIROS!E:E,$B79)=1,"PENDIENTE ELIMINAR",IF(COUNTIFS(ASIGNACIONES!$D:$D,$B79,ASIGNACIONES!$H:$H,E79,ASIGNACIONES!$G:$G,$D79,ASIGNACIONES!$J:$J,$F79)=0,"NUEVO","ACTIVO"))))
H80: =IF($B80="","",IF($B80="TRANSCARNES","ACTIVO",IF(COUNTIF(RETIROS!E:E,$B80)=1,"PENDIENTE ELIMINAR",IF(COUNTIFS(ASIGNACIONES!$D:$D,$B80,ASIGNACIONES!$H:$H,E80,ASIGNACIONES!$G:$G,$D80,ASIGNACIONES!$J:$J,$F80)=0,"NUEVO","ACTIVO"))))
H81: =IF($B81="","",IF($B81="TRANSCARNES","ACTIVO",IF(COUNTIF(RETIROS!E:E,$B81)=1,"PENDIENTE ELIMINAR",IF(COUNTIFS(ASIGNACIONES!$D:$D,$B81,ASIGNACIONES!$H:$H,E81,ASIGNACIONES!$G:$G,$D81,ASIGNACIONES!$J:$J,$F81)=0,"NUEVO","ACTIVO"))))
H82: =IF($B82="","",IF($B82="TRANSCARNES","ACTIVO",IF(COUNTIF(RETIROS!E:E,$B82)=1,"PENDIENTE ELIMINAR",IF(COUNTIFS(ASIGNACIONES!$D:$D,$B82,ASIGNACIONES!$H:$H,E82,ASIGNACIONES!$G:$G,$D82,ASIGNACIONES!$J:$J,$F82)=0,"NUEVO","ACTIVO"))))
H83: =IF($B83="","",IF($B83="TRANSCARNES","ACTIVO",IF(COUNTIF(RETIROS!E:E,$B83)=1,"PENDIENTE ELIMINAR",IF(COUNTIFS(ASIGNACIONES!$D:$D,$B83,ASIGNACIONES!$H:$H,E83,ASIGNACIONES!$G:$G,$D83,ASIGNACIONES!$J:$J,$F83)=0,"NUEVO","ACTIVO"))))
H84: =IF($B84="","",IF($B84="TRANSCARNES","ACTIVO",IF(COUNTIF(RETIROS!E:E,$B84)=1,"PENDIENTE ELIMINAR",IF(COUNTIFS(ASIGNACIONES!$D:$D,$B84,ASIGNACIONES!$H:$H,E84,ASIGNACIONES!$G:$G,$D84,ASIGNACIONES!$J:$J,$F84)=0,"NUEVO","ACTIVO"))))
... H869: =IF($B869="","",IF($B869="TRANSCARNES","ACTIVO",IF(COUNTIF(RETIROS!E:E,$B869)=1,"PENDIENTE ELIMINAR",IF(COUNTIFS(ASIGNACIONES!$D:$D,$B869,ASIGNACIONES!$H:$H,E869,ASIGNACIONES!$G:$G,$D869,ASIGNACIONES!$J:$J,$F869)=0,"NUEVO","ACTIVO"))))

Sheet RETIROS
A1: ID RETIRO | B1: identificacion | C1: Codigo de Dotacion | D1: Fecha de Retiro | E1: Operario | F1: Codigo de Lockets | G1: Area | H1: Talla de Operarios | I1: Talla de dotacion asignada | J1: Area de Lockers | K1: Observaciones | L1: Imagen
A2: 8c37afde | B2: 1052218087 | C2: 023 | D2: 45164 | E2: QUIÑONES CÁRCAMO ANDRÉS FELIPE | F2: LOG-01 | G2: LOG | H2: M | I2: M | J2: VESTIDOR HOMBRES
A3: 9ab71c59 | B3: 1098666215 | C3: 026 | D3: 45164 | E3: RODRIGUEZ RUEDA ORLANDO | F3: LOG-04 | G3: LOG | H3: M | I3: M | J3: VESTIDOR HOMBRES
A4: ea024a24 | B4: 1232892424 | D4: 45164 | E4: JAIMES FONSECA IVAN RAMIRO | F4: LOG-07 | G4: LOG | H4: M | J4: VESTIDOR HOMBRES
A5: f66bd158 | B5: 1005369411 | C5: 067 | D5: 45164 | E5: ALMANZA MANRIQUE DILSON STIWARD | F5: LOG-02 | G5: LOG | H5: M | I5: M | J5: VESTIDOR HOMBRES
A6: 27a4880f | B6: 1098623058 | C6: 016 | D6: 45170 | E6: HERRERA AFANADOR ERWIN | F6: DES-16 | G6: DES | H6: L | I6: L | J6: VESTIDOR HOMBRES
A7: 784ec265 | B7: 1098805752 | C7: 064 | D7: 45170 | E7: SANDOVAL JAIMES CRISTHIAN CAMILO | F7: DES-30 | G7: DES | H7: XL | I7: XL | J7: VESTIDOR HOMBRES
A8: f7a55122 | B8: 13872972 | C8: 024 | D8: 45232 | E8: CACERES FREDDY | F8: CAL-01 | G8: CAL | H8: L | I8: L | J8: ADMINISTRACION
A9: d5a13fd6 | B9: 1098791772 | C9: 013 | D9: 45240 | E9: LOPEZ MANTILLA JHON FREDDY | F9: DES-19 | G9: DES | H9: L | I9: L | J9: VESTIDOR HOMBRES
A10: c88e2f71 | B10: 1005108421 | C10: 035 | D10: 45240 | E10: SANCHEZ ORTEGA JUAN PABLO | F10: DES-23 | G10: DES | H10: L | I10: L | J10: VESTIDOR HOMBRES
A11: 5d347585 | B11: 1095827638 | C11: 109 | D11: 45241 | E11: DURAN AVILA ANDERSON HARLEY | F11: LOG-07 | G11: LOG | H11: M | I11: M | J11: VESTIDOR HOMBRES
A12: 30fc63e1 | B12: 1102381907 | C12: 068 | D12: 45248 | E12: DURAN BURGOS OSCAR FERNANDO | F12: CAL-01 | G12: CAL | H12: L | I12: L | J12: ADMINISTRACION
A13: 00b49ab9 | B13: 1098700957 | C13: 102 | D13: 45250 | E13: PARRA DURAN JAVIER ORLANDO | F13: SST-01 | G13: SST | H13: XXXL | I13: XXXL | J13: VESTIDOR HOMBRES
A14: c452cb7d | B14: 1098618560 | C14: 054 | D14: 45250 | E14: ARAQUE HERRERA DIEGO JAVIER | F14: LOG-01 | G14: LOG | H14: XL | I14: XL | J14: VESTIDOR HOMBRES
A15: 6d6c2f25 | B15: 1148454856 | C15: 042 | D15: 45257 | E15: ARANDA FERRER MARLON GREGORY | F15: DES-14 | G15: DES | H15: XL | I15: XL | J15: VESTIDOR HOMBRES
A16: c5e74dc2 | B16: 1095944205 | C16: 072 | D16: 45261 | E16: JUAN JOSE NARANJO RUEDA | F16: LOG-08 | G16: LOG | H16: L | I16: L | J16: VESTIDOR HOMBRES
... A75: 2ffb03c9 | B75: 1095812471 | C75: 006 | D75: 45905 | E75: MEDINA MALDONADO DARWIN JULIÁN | F75: LOG-07 | G75: LOG | H75: XXL | I75: XXL | J75: VESTIDOR HOMBRES

Sheet OPERARIOS
A1: id | B1: operarios nuevo
A2: =IFERROR(__xludf.DUMMYFUNCTION("FILTER(PERSONAL!$B:$B,PERSONAL!$H:$H=""NUEVO"")"),"TIC 1") -> TIC 1 | B2: =IFERROR(__xludf.DUMMYFUNCTION("FILTER(PERSONAL!$B:$B,PERSONAL!$H:$H=""NUEVO"")"),"TIC 1") -> TIC 1
A3: =IFERROR(__xludf.DUMMYFUNCTION("""COMPUTED_VALUE"""),"ARIAS PARADA JHONATAN DAVID") -> ARIAS PARADA JHONATAN DAVID | B3: =IFERROR(__xludf.DUMMYFUNCTION("""COMPUTED_VALUE"""),"ARIAS PARADA JHONATAN DAVID") -> ARIAS PARADA JHONATAN DAVID
A4: =IFERROR(__xludf.DUMMYFUNCTION("""COMPUTED_VALUE"""),"FIGUEREDO SANMILLAN ALEXANDER") -> FIGUEREDO SANMILLAN ALEXANDER | B4: =IFERROR(__xludf.DUMMYFUNCTION("""COMPUTED_VALUE"""),"FIGUEREDO SANMILLAN ALEXANDER") -> FIGUEREDO SANMILLAN ALEXANDER

Sheet DOTACIONES
A1: Cantidad | B1: Codigo de Dotacion | C1: Area de USO | D1: Talla | E1: ESTADO
A2: 3 | B2: 001 | C2: PROCESO | D2: XXXL | E2: =IF(B2="","",IF(A2=0,"NO HAY ESE CODIGO",IF(COUNTIF(ASIGNACIONES!$B$3:$B949,B2)=1,"DOTACION ASIGNADA",IF(C2="VISITAS","DOTACION VISITA",IF(C2="MTTO","DOTACION MTTO",IF(C2="PLANTA EMERGENCIA","DOTACION RES DE EMERGENCIA",IF(C2="EXTERNOS","DOTACION DE EXTERNO","DOTACION DISPONIBLE"))))))) -> DOTACION ASIGNADA
A3: 3 | B3: 002 | C3: PROCESO | D3: XL | E3: =IF(B3="","",IF(A3=0,"NO HAY ESE CODIGO",IF(COUNTIF(ASIGNACIONES!$B$3:$B949,B3)=1,"DOTACION ASIGNADA",IF(C3="VISITAS","DOTACION VISITA",IF(C3="MTTO","DOTACION MTTO",IF(C3="PLANTA EMERGENCIA","DOTACION RES DE EMERGENCIA",IF(C3="EXTERNOS","DOTACION DE EXTERNO","DOTACION DISPONIBLE"))))))) -> DOTACION ASIGNADA
A4: 3 | B4: 003 | C4: PROCESO | D4: XL | E4: =IF(B4="","",IF(A4=0,"NO HAY ESE CODIGO",IF(COUNTIF(ASIGNACIONES!$B$3:$B949,B4)=1,"DOTACION ASIGNADA",IF(C4="VISITAS","DOTACION VISITA",IF(C4="MTTO","DOTACION MTTO",IF(C4="PLANTA EMERGENCIA","DOTACION RES DE EMERGENCIA",IF(C4="EXTERNOS","DOTACION DE EXTERNO","DOTACION DISPONIBLE"))))))) -> DOTACION ASIGNADA
A5: 0 | B5: 004 | C5: PROCESO | D5: L | E5: =IF(B5="","",IF(A5=0,"NO HAY ESE CODIGO",IF(COUNTIF(ASIGNACIONES!$B$3:$B949,B5)=1,"DOTACION ASIGNADA",IF(C5="VISITAS","DOTACION VISITA",IF(C5="MTTO","DOTACION MTTO",IF(C5="PLANTA EMERGENCIA","DOTACION RES DE EMERGENCIA",IF(C5="EXTERNOS","DOTACION DE EXTERNO","DOTACION DISPONIBLE"))))))) -> NO HAY ESE CODIGO
A6: 0 | B6: 005 | C6: PROCESO | D6: M | E6: =IF(B6="","",IF(A6=0,"NO HAY ESE CODIGO",IF(COUNTIF(ASIGNACIONES!$B$3:$B949,B6)=1,"DOTACION ASIGNADA",IF(C6="VISITAS","DOTACION VISITA",IF(C6="MTTO","DOTACION MTTO",IF(C6="PLANTA EMERGENCIA","DOTACION RES DE EMERGENCIA",IF(C6="EXTERNOS","DOTACION DE EXTERNO","DOTACION DISPONIBLE"))))))) -> NO HAY ESE CODIGO
A7: 3 | B7: 006 | C7: PROCESO | D7: XXL | E7: =IF(B7="","",IF(A7=0,"NO HAY ESE CODIGO",IF(COUNTIF(ASIGNACIONES!$B$3:$B949,B7)=1,"DOTACION ASIGNADA",IF(C7="VISITAS","DOTACION VISITA",IF(C7="MTTO","DOTACION MTTO",IF(C7="PLANTA EMERGENCIA","DOTACION RES DE EMERGENCIA",IF(C7="EXTERNOS","DOTACION DE EXTERNO","DOTACION DISPONIBLE"))))))) -> DOTACION DISPONIBLE
A8: 3 | B8: 007 | C8: PROCESO | D8: L | E8: =IF(B8="","",IF(A8=0,"NO HAY ESE CODIGO",IF(COUNTIF(ASIGNACIONES!$B$3:$B949,B8)=1,"DOTACION ASIGNADA",IF(C8="VISITAS","DOTACION VISITA",IF(C8="MTTO","DOTACION MTTO",IF(C8="PLANTA EMERGENCIA","DOTACION RES DE EMERGENCIA",IF(C8="EXTERNOS","DOTACION DE EXTERNO","DOTACION DISPONIBLE"))))))) -> DOTACION ASIGNADA
A9: 3 | B9: 008 | C9: PROCESO | D9: XXL | E9: =IF(B9="","",IF(A9=0,"NO HAY ESE CODIGO",IF(COUNTIF(ASIGNACIONES!$B$3:$B949,B9)=1,"DOTACION ASIGNADA",IF(C9="VISITAS","DOTACION VISITA",IF(C9="MTTO","DOTACION MTTO",IF(C9="PLANTA EMERGENCIA","DOTACION RES DE EMERGENCIA",IF(C9="EXTERNOS","DOTACION DE EXTERNO","DOTACION DISPONIBLE"))))))) -> DOTACION ASIGNADA
A10: 3 | B10: 009 | C10: PROCESO | D10: L | E10: =IF(B10="","",IF(A10=0,"NO HAY ESE CODIGO",IF(COUNTIF(ASIGNACIONES!$B$3:$B949,B10)=1,"DOTACION ASIGNADA",IF(C10="VISITAS","DOTACION VISITA",IF(C10="MTTO","DOTACION MTTO",IF(C10="PLANTA EMERGENCIA","DOTACION RES DE EMERGENCIA",IF(C10="EXTERNOS","DOTACION DE EXTERNO","DOTACION DISPONIBLE"))))))) -> DOTACION ASIGNADA
A11: 3 | B11: 010 | C11: PROCESO | D11: L | E11: =IF(B11="","",IF(A11=0,"NO HAY ESE CODIGO",IF(COUNTIF(ASIGNACIONES!$B$3:$B949,B11)=1,"DOTACION ASIGNADA",IF(C11="VISITAS","DOTACION VISITA",IF(C11="MTTO","DOTACION MTTO",IF(C11="PLANTA EMERGENCIA","DOTACION RES DE EMERGENCIA",IF(C11="EXTERNOS","DOTACION DE EXTERNO","DOTACION DISPONIBLE"))))))) -> DOTACION ASIGNADA
A12: 1 | B12: 011 | C12: PROCESO | D12: S | E12: =IF(B12="","",IF(A12=0,"NO HAY ESE CODIGO",IF(COUNTIF(ASIGNACIONES!$B$3:$B949,B12)=1,"DOTACION ASIGNADA",IF(C12="VISITAS","DOTACION VISITA",IF(C12="MTTO","DOTACION MTTO",IF(C12="PLANTA EMERGENCIA","DOTACION RES DE EMERGENCIA",IF(C12="EXTERNOS","DOTACION DE EXTERNO","DOTACION DISPONIBLE"))))))) -> DOTACION DISPONIBLE
A13: 2 | B13: 012 | C13: PROCESO | D13: M | E13: =IF(B13="","",IF(A13=0,"NO HAY ESE CODIGO",IF(COUNTIF(ASIGNACIONES!$B$3:$B949,B13)=1,"DOTACION ASIGNADA",IF(C13="VISITAS","DOTACION VISITA",IF(C13="MTTO","DOTACION MTTO",IF(C13="PLANTA EMERGENCIA","DOTACION RES DE EMERGENCIA",IF(C13="EXTERNOS","DOTACION DE EXTERNO","DOTACION DISPONIBLE"))))))) -> DOTACION DISPONIBLE
A14: 3 | B14: 013 | C14: PROCESO | D14: L | E14: =IF(B14="","",IF(A14=0,"NO HAY ESE CODIGO",IF(COUNTIF(ASIGNACIONES!$B$3:$B949,B14)=1,"DOTACION ASIGNADA",IF(C14="VISITAS","DOTACION VISITA",IF(C14="MTTO","DOTACION MTTO",IF(C14="PLANTA EMERGENCIA","DOTACION RES DE EMERGENCIA",IF(C14="EXTERNOS","DOTACION DE EXTERNO","DOTACION DISPONIBLE"))))))) -> DOTACION ASIGNADA
A15: 3 | B15: 014 | C15: PROCESO | D15: XXL | E15: =IF(B15="","",IF(A15=0,"NO HAY ESE CODIGO",IF(COUNTIF(ASIGNACIONES!$B$3:$B949,B15)=1,"DOTACION ASIGNADA",IF(C15="VISITAS","DOTACION VISITA",IF(C15="MTTO","DOTACION MTTO",IF(C15="PLANTA EMERGENCIA","DOTACION RES DE EMERGENCIA",IF(C15="EXTERNOS","DOTACION DE EXTERNO","DOTACION DISPONIBLE"))))))) -> DOTACION ASIGNADA
A16: 3 | B16: 015 | C16: PROCESO | D16: M | E16: =IF(B16="","",IF(A16=0,"NO HAY ESE CODIGO",IF(COUNTIF(ASIGNACIONES!$B$3:$B949,B16)=1,"DOTACION ASIGNADA",IF(C16="VISITAS","DOTACION VISITA",IF(C16="MTTO","DOTACION MTTO",IF(C16="PLANTA EMERGENCIA","DOTACION RES DE EMERGENCIA",IF(C16="EXTERNOS","DOTACION DE EXTERNO","DOTACION DISPONIBLE"))))))) -> DOTACION DISPONIBLE
A17: 3 | B17: 016 | C17: PROCESO | D17: L | E17: =IF(B17="","",IF(A17=0,"NO HAY ESE CODIGO",IF(COUNTIF(ASIGNACIONES!$B$3:$B949,B17)=1,"DOTACION ASIGNADA",IF(C17="VISITAS","DOTACION VISITA",IF(C17="MTTO","DOTACION MTTO",IF(C17="PLANTA EMERGENCIA","DOTACION RES DE EMERGENCIA",IF(C17="EXTERNOS","DOTACION DE EXTERNO","DOTACION DISPONIBLE"))))))) -> DOTACION DISPONIBLE
A18: 3 | B18: 017 | C18: PROCESO | D18: XXL | E18: =IF(B18="","",IF(A18=0,"NO HAY ESE CODIGO",IF(COUNTIF(ASIGNACIONES!$B$3:$B949,B18)=1,"DOTACION ASIGNADA",IF(C18="VISITAS","DOTACION VISITA",IF(C18="MTTO","DOTACION MTTO",IF(C18="PLANTA EMERGENCIA","DOTACION RES DE EMERGENCIA",IF(C18="EXTERNOS","DOTACION DE EXTERNO","DOTACION DISPONIBLE"))))))) -> DOTACION ASIGNADA
A19: 3 | B19: 018 | C19: PROCESO | D19: L | E19: =IF(B19="","",IF(A19=0,"NO HAY ESE CODIGO",IF(COUNTIF(ASIGNACIONES!$B$3:$B949,B19)=1,"DOTACION ASIGNADA",IF(C19="VISITAS","DOTACION VISITA",IF(C19="MTTO","DOTACION MTTO",IF(C19="PLANTA EMERGENCIA","DOTACION RES DE EMERGENCIA",IF(C19="EXTERNOS","DOTACION DE EXTERNO","DOTACION DISPONIBLE"))))))) -> DOTACION ASIGNADA
A20: 0 | B20: 019 | C20: PROCESO | D20: M | E20: =IF(B20="","",IF(A20=0,"NO HAY ESE CODIGO",IF(COUNTIF(ASIGNACIONES!$B$3:$B949,B20)=1,"DOTACION ASIGNADA",IF(C20="VISITAS","DOTACION VISITA",IF(C20="MTTO","DOTACION MTTO",IF(C20="PLANTA EMERGENCIA","DOTACION RES DE EMERGENCIA",IF(C20="EXTERNOS","DOTACION DE EXTERNO","DOTACION DISPONIBLE"))))))) -> NO HAY ESE CODIGO
A21: 3 | B21: 020 | C21: PROCESO | D21: L | E21: =IF(B21="","",IF(A21=0,"NO HAY ESE CODIGO",IF(COUNTIF(ASIGNACIONES!$B$3:$B949,B21)=1,"DOTACION ASIGNADA",IF(C21="VISITAS","DOTACION VISITA",IF(C21="MTTO","DOTACION MTTO",IF(C21="PLANTA EMERGENCIA","DOTACION RES DE EMERGENCIA",IF(C21="EXTERNOS","DOTACION DE EXTERNO","DOTACION DISPONIBLE"))))))) -> DOTACION ASIGNADA
A22: 3 | B22: 021 | C22: PROCESO | D22: L | E22: =IF(B22="","",IF(A22=0,"NO HAY ESE CODIGO",IF(COUNTIF(ASIGNACIONES!$B$3:$B949,B22)=1,"DOTACION ASIGNADA",IF(C22="VISITAS","DOTACION VISITA",IF(C22="MTTO","DOTACION MTTO",IF(C22="PLANTA EMERGENCIA","DOTACION RES DE EMERGENCIA",IF(C22="EXTERNOS","DOTACION DE EXTERNO","DOTACION DISPONIBLE"))))))) -> DOTACION ASIGNADA
A23: 3 | B23: 022 | C23: PROCESO | D23: M | E23: =IF(B23="","",IF(A23=0,"NO HAY ESE CODIGO",IF(COUNTIF(ASIGNACIONES!$B$3:$B949,B23)=1,"DOTACION ASIGNADA",IF(C23="VISITAS","DOTACION VISITA",IF(C23="MTTO","DOTACION MTTO",IF(C23="PLANTA EMERGENCIA","DOTACION RES DE EMERGENCIA",IF(C23="EXTERNOS","DOTACION DE EXTERNO","DOTACION DISPONIBLE"))))))) -> DOTACION ASIGNADA
A24: 0 | B24: 023 | C24: PROCESO | D24: M | E24: =IF(B24="","",IF(A24=0,"NO HAY ESE CODIGO",IF(COUNTIF(ASIGNACIONES!$B$3:$B949,B24)=1,"DOTACION ASIGNADA",IF(C24="VISITAS","DOTACION VISITA",IF(C24="MTTO","DOTACION MTTO",IF(C24="PLANTA EMERGENCIA","DOTACION RES DE EMERGENCIA",IF(C24="EXTERNOS","DOTACION DE EXTERNO","DOTACION DISPONIBLE"))))))) -> NO HAY ESE CODIGO
A25: 1 | B25: 024 | C25: PROCESO | D25: L | E25: =IF(B25="","",IF(A25=0,"NO HAY ESE CODIGO",IF(COUNTIF(ASIGNACIONES!$B$3:$B949,B25)=1,"DOTACION ASIGNADA",IF(C25="VISITAS","DOTACION VISITA",IF(C25="MTTO","DOTACION MTTO",IF(C25="PLANTA EMERGENCIA","DOTACION RES DE EMERGENCIA",IF(C25="EXTERNOS","DOTACION DE EXTERNO","DOTACION DISPONIBLE"))))))) -> DOTACION DISPONIBLE
A26: 3 | B26: 025 | C26: PROCESO | D26: XL | E26: =IF(B26="","",IF(A26=0,"NO HAY ESE CODIGO",IF(COUNTIF(ASIGNACIONES!$B$3:$B949,B26)=1,"DOTACION ASIGNADA",IF(C26="VISITAS","DOTACION VISITA",IF(C26="MTTO","DOTACION MTTO",IF(C26="PLANTA EMERGENCIA","DOTACION RES DE EMERGENCIA",IF(C26="EXTERNOS","DOTACION DE EXTERNO","DOTACION DISPONIBLE"))))))) -> DOTACION ASIGNADA
A27: 3 | B27: 026 | C27: PROCESO | D27: M | E27: =IF(B27="","",IF(A27=0,"NO HAY ESE CODIGO",IF(COUNTIF(ASIGNACIONES!$B$3:$B949,B27)=1,"DOTACION ASIGNADA",IF(C27="VISITAS","DOTACION VISITA",IF(C27="MTTO","DOTACION MTTO",IF(C27="PLANTA EMERGENCIA","DOTACION RES DE EMERGENCIA",IF(C27="EXTERNOS","DOTACION DE EXTERNO","DOTACION DISPONIBLE"))))))) -> DOTACION DISPONIBLE
A28: 0 | B28: 027 | C28: PROCESO | D28: L | E28: =IF(B28="","",IF(A28=0,"NO HAY ESE CODIGO",IF(COUNTIF(ASIGNACIONES!$B$3:$B949,B28)=1,"DOTACION ASIGNADA",IF(C28="VISITAS","DOTACION VISITA",IF(C28="MTTO","DOTACION MTTO",IF(C28="PLANTA EMERGENCIA","DOTACION RES DE EMERGENCIA",IF(C28="EXTERNOS","DOTACION DE EXTERNO","DOTACION DISPONIBLE"))))))) -> NO HAY ESE CODIGO
A29: 3 | B29: 028 | C29: PROCESO | D29: L | E29: =IF(B29="","",IF(A29=0,"NO HAY ESE CODIGO",IF(COUNTIF(ASIGNACIONES!$B$3:$B949,B29)=1,"DOTACION ASIGNADA",IF(C29="VISITAS","DOTACION VISITA",IF(C29="MTTO","DOTACION MTTO",IF(C29="PLANTA EMERGENCIA","DOTACION RES DE EMERGENCIA",IF(C29="EXTERNOS","DOTACION DE EXTERNO","DOTACION DISPONIBLE"))))))) -> DOTACION ASIGNADA
A30: 0 | B30: 029 | C30: PROCESO | D30: S | E30: =IF(B30="","",IF(A30=0,"NO HAY ESE CODIGO",IF(COUNTIF(ASIGNACIONES!$B$3:$B949,B30)=1,"DOTACION ASIGNADA",IF(C30="VISITAS","DOTACION VISITA",IF(C30="MTTO","DOTACION MTTO",IF(C30="PLANTA EMERGENCIA","DOTACION RES DE EMERGENCIA",IF(C30="EXTERNOS","DOTACION DE EXTERNO","DOTACION DISPONIBLE"))))))) -> NO HAY ESE CODIGO
A31: 3 | B31: 030 | C31: PROCESO | D31: M | E31: =IF(B31="","",IF(A31=0,"NO HAY ESE CODIGO",IF(COUNTIF(ASIGNACIONES!$B$3:$B949,B31)=1,"DOTACION ASIGNADA",IF(C31="VISITAS","DOTACION VISITA",IF(C31="MTTO","DOTACION MTTO",IF(C31="PLANTA EMERGENCIA","DOTACION RES DE EMERGENCIA",IF(C31="EXTERNOS","DOTACION DE EXTERNO","DOTACION DISPONIBLE"))))))) -> DOTACION ASIGNADA
A32: 3 | B32: 031 | C32: PROCESO | D32: M | E32: =IF(B32="","",IF(A32=0,"NO HAY ESE CODIGO",IF(COUNTIF(ASIGNACIONES!$B$3:$B949,B32)=1,"DOTACION ASIGNADA",IF(C32="VISITAS","DOTACION VISITA",IF(C32="MTTO","DOTACION MTTO",IF(C32="PLANTA EMERGENCIA","DOTACION RES DE EMERGENCIA",IF(C32="EXTERNOS","DOTACION DE EXTERNO","DOTACION DISPONIBLE"))))))) -> DOTACION DISPONIBLE
A33: 3 | B33: 032 | C33: PROCESO | D33: M | E33: =IF(B33="","",IF(A33=0,"NO HAY ESE CODIGO",IF(COUNTIF(ASIGNACIONES!$B$3:$B949,B33)=1,"DOTACION ASIGNADA",IF(C33="VISITAS","DOTACION VISITA",IF(C33="MTTO","DOTACION MTTO",IF(C33="PLANTA EMERGENCIA","DOTACION RES DE EMERGENCIA",IF(C33="EXTERNOS","DOTACION DE EXTERNO","DOTACION DISPONIBLE"))))))) -> DOTACION DISPONIBLE
A34: 3 | B34: 033 | C34: PROCESO | D34: L | E34: =IF(B34="","",IF(A34=0,"NO HAY ESE CODIGO",IF(COUNTIF(ASIGNACIONES!$B$3:$B949,B34)=1,"DOTACION ASIGNADA",IF(C34="VISITAS","DOTACION VISITA",IF(C34="MTTO","DOTACION MTTO",IF(C34="PLANTA EMERGENCIA","DOTACION RES DE EMERGENCIA",IF(C34="EXTERNOS","DOTACION DE EXTERNO","DOTACION DISPONIBLE"))))))) -> DOTACION ASIGNADA
A35: 3 | B35: 034 | C35: PROCESO | D35: L | E35: =IF(B35="","",IF(A35=0,"NO HAY ESE CODIGO",IF(COUNTIF(ASIGNACIONES!$B$3:$B949,B35)=1,"DOTACION ASIGNADA",IF(C35="VISITAS","DOTACION VISITA",IF(C35="MTTO","DOTACION MTTO",IF(C35="PLANTA EMERGENCIA","DOTACION RES DE EMERGENCIA",IF(C35="EXTERNOS","DOTACION DE EXTERNO","DOTACION DISPONIBLE"))))))) -> DOTACION DISPONIBLE
A36: 3 | B36: 035 | C36: PROCESO | D36: L | E36: =IF(B36="","",IF(A36=0,"NO HAY ESE CODIGO",IF(COUNTIF(ASIGNACIONES!$B$3:$B949,B36)=1,"DOTACION ASIGNADA",IF(C36="VISITAS","DOTACION VISITA",IF(C36="MTTO","DOTACION MTTO",IF(C36="PLANTA EMERGENCIA","DOTACION RES DE EMERGENCIA",IF(C36="EXTERNOS","DOTACION DE EXTERNO","DOTACION DISPONIBLE"))))))) -> DOTACION DISPONIBLE
A37: 3 | B37: 036 | C37: PROCESO | D37: XL | E37: =IF(B37="","",IF(A37=0,"NO HAY ESE CODIGO",IF(COUNTIF(ASIGNACIONES!$B$3:$B949,B37)=1,"DOTACION ASIGNADA",IF(C37="VISITAS","DOTACION VISITA",IF(C37="MTTO","DOTACION MTTO",IF(C37="PLANTA EMERGENCIA","DOTACION RES DE EMERGENCIA",IF(C37="EXTERNOS","DOTACION DE EXTERNO","DOTACION DISPONIBLE"))))))) -> DOTACION ASIGNADA
A38: 0 | B38: 037 | C38: PROCESO | D38: M | E38: =IF(B38="","",IF(A38=0,"NO HAY ESE CODIGO",IF(COUNTIF(ASIGNACIONES!$B$3:$B949,B38)=1,"DOTACION ASIGNADA",IF(C38="VISITAS","DOTACION VISITA",IF(C38="MTTO","DOTACION MTTO",IF(C38="PLANTA EMERGENCIA","DOTACION RES DE EMERGENCIA",IF(C38="EXTERNOS","DOTACION DE EXTERNO","DOTACION DISPONIBLE"))))))) -> NO HAY ESE CODIGO
A39: 3 | B39: 038 | C39: PROCESO | D39: L | E39: =IF(B39="","",IF(A39=0,"NO HAY ESE CODIGO",IF(COUNTIF(ASIGNACIONES!$B$3:$B949,B39)=1,"DOTACION ASIGNADA",IF(C39="VISITAS","DOTACION VISITA",IF(C39="MTTO","DOTACION MTTO",IF(C39="PLANTA EMERGENCIA","DOTACION RES DE EMERGENCIA",IF(C39="EXTERNOS","DOTACION DE EXTERNO","DOTACION DISPONIBLE"))))))) -> DOTACION ASIGNADA
A40: 0 | B40: 039 | C40: PROCESO | D40: M | E40: =IF(B40="","",IF(A40=0,"NO HAY ESE CODIGO",IF(COUNTIF(ASIGNACIONES!$B$3:$B949,B40)=1,"DOTACION ASIGNADA",IF(C40="VISITAS","DOTACION VISITA",IF(C40="MTTO","DOTACION MTTO",IF(C40="PLANTA EMERGENCIA","DOTACION RES DE EMERGENCIA",IF(C40="EXTERNOS","DOTACION DE EXTERNO","DOTACION DISPONIBLE"))))))) -> NO HAY ESE CODIGO
...

Sheet DOTACIONES DISPONIBLES
A1: CODIGO DE DOTACION | B1: TALLA | C1: CANTIDAD
A2: =IFERROR(__xludf.DUMMYFUNCTION("FILTER(DOTACIONES!B:B,DOTACIONES!$E:$E=""DOTACION DISPONIBLE"")"),"006") -> 006 | B2: =IFERROR(__xludf.DUMMYFUNCTION("FILTER(DOTACIONES!D:D,DOTACIONES!$E:$E=""DOTACION DISPONIBLE"")"),"XXL") -> XXL | C2: =IFERROR(__xludf.DUMMYFUNCTION("FILTER(DOTACIONES!A:A,DOTACIONES!$E:$E=""DOTACION DISPONIBLE"")"),3.0) -> 3
A3: =IFERROR(__xludf.DUMMYFUNCTION("""COMPUTED_VALUE"""),"011") -> 011 | B3: =IFERROR(__xludf.DUMMYFUNCTION("""COMPUTED_VALUE"""),"S") -> S | C3: =IFERROR(__xludf.DUMMYFUNCTION("""COMPUTED_VALUE"""),1.0) -> 1
A4: =IFERROR(__xludf.DUMMYFUNCTION("""COMPUTED_VALUE"""),"012") -> 012 | B4: =IFERROR(__xludf.DUMMYFUNCTION("""COMPUTED_VALUE"""),"M") -> M | C4: =IFERROR(__xludf.DUMMYFUNCTION("""COMPUTED_VALUE"""),2.0) -> 2
A5: =IFERROR(__xludf.DUMMYFUNCTION("""COMPUTED_VALUE"""),"015") -> 015 | B5: =IFERROR(__xludf.DUMMYFUNCTION("""COMPUTED_VALUE"""),"M") -> M | C5: =IFERROR(__xludf.DUMMYFUNCTION("""COMPUTED_VALUE"""),3.0) -> 3
A6: =IFERROR(__xludf.DUMMYFUNCTION("""COMPUTED_VALUE"""),"016") -> 016 | B6: =IFERROR(__xludf.DUMMYFUNCTION("""COMPUTED_VALUE"""),"L") -> L | C6: =IFERROR(__xludf.DUMMYFUNCTION("""COMPUTED_VALUE"""),3.0) -> 3
A7: =IFERROR(__xludf.DUMMYFUNCTION("""COMPUTED_VALUE"""),"024") -> 024 | B7: =IFERROR(__xludf.DUMMYFUNCTION("""COMPUTED_VALUE"""),"L") -> L | C7: =IFERROR(__xludf.DUMMYFUNCTION("""COMPUTED_VALUE"""),1.0) -> 1
A8: =IFERROR(__xludf.DUMMYFUNCTION("""COMPUTED_VALUE"""),"026") -> 026 | B8: =IFERROR(__xludf.DUMMYFUNCTION("""COMPUTED_VALUE"""),"M") -> M | C8: =IFERROR(__xludf.DUMMYFUNCTION("""COMPUTED_VALUE"""),3.0) -> 3
A9: =IFERROR(__xludf.DUMMYFUNCTION("""COMPUTED_VALUE"""),"031") -> 031 | B9: =IFERROR(__xludf.DUMMYFUNCTION("""COMPUTED_VALUE"""),"M") -> M | C9: =IFERROR(__xludf.DUMMYFUNCTION("""COMPUTED_VALUE"""),3.0) -> 3
A10: =IFERROR(__xludf.DUMMYFUNCTION("""COMPUTED_VALUE"""),"032") -> 032 | B10: =IFERROR(__xludf.DUMMYFUNCTION("""COMPUTED_VALUE"""),"M") -> M | C10: =IFERROR(__xludf.DUMMYFUNCTION("""COMPUTED_VALUE"""),3.0) -> 3
A11: =IFERROR(__xludf.DUMMYFUNCTION("""COMPUTED_VALUE"""),"034") -> 034 | B11: =IFERROR(__xludf.DUMMYFUNCTION("""COMPUTED_VALUE"""),"L") -> L | C11: =IFERROR(__xludf.DUMMYFUNCTION("""COMPUTED_VALUE"""),3.0) -> 3
A12: =IFERROR(__xludf.DUMMYFUNCTION("""COMPUTED_VALUE"""),"035") -> 035 | B12: =IFERROR(__xludf.DUMMYFUNCTION("""COMPUTED_VALUE"""),"L") -> L | C12: =IFERROR(__xludf.DUMMYFUNCTION("""COMPUTED_VALUE"""),3.0) -> 3
A13: =IFERROR(__xludf.DUMMYFUNCTION("""COMPUTED_VALUE"""),"042") -> 042 | B13: =IFERROR(__xludf.DUMMYFUNCTION("""COMPUTED_VALUE"""),"XL") -> XL | C13: =IFERROR(__xludf.DUMMYFUNCTION("""COMPUTED_VALUE"""),3.0) -> 3
A14: =IFERROR(__xludf.DUMMYFUNCTION("""COMPUTED_VALUE"""),"045") -> 045 | B14: =IFERROR(__xludf.DUMMYFUNCTION("""COMPUTED_VALUE"""),"L") -> L | C14: =IFERROR(__xludf.DUMMYFUNCTION("""COMPUTED_VALUE"""),1.0) -> 1
A15: =IFERROR(__xludf.DUMMYFUNCTION("""COMPUTED_VALUE"""),"053") -> 053 | B15: =IFERROR(__xludf.DUMMYFUNCTION("""COMPUTED_VALUE"""),"L") -> L | C15: =IFERROR(__xludf.DUMMYFUNCTION("""COMPUTED_VALUE"""),1.0) -> 1
A16: =IFERROR(__xludf.DUMMYFUNCTION("""COMPUTED_VALUE"""),"056") -> 056 | B16: =IFERROR(__xludf.DUMMYFUNCTION("""COMPUTED_VALUE"""),"XL") -> XL | C16: =IFERROR(__xludf.DUMMYFUNCTION("""COMPUTED_VALUE"""),3.0) -> 3
A17: =IFERROR(__xludf.DUMMYFUNCTION("""COMPUTED_VALUE"""),"068") -> 068 | B17: =IFERROR(__xludf.DUMMYFUNCTION("""COMPUTED_VALUE"""),"L") -> L | C17: =IFERROR(__xludf.DUMMYFUNCTION("""COMPUTED_VALUE"""),3.0) -> 3
A18: =IFERROR(__xludf.DUMMYFUNCTION("""COMPUTED_VALUE"""),"080") -> 080 | B18: =IFERROR(__xludf.DUMMYFUNCTION("""COMPUTED_VALUE"""),"XL") -> XL | C18: =IFERROR(__xludf.DUMMYFUNCTION("""COMPUTED_VALUE"""),3.0) -> 3
A19: =IFERROR(__xludf.DUMMYFUNCTION("""COMPUTED_VALUE"""),"100") -> 100 | B19: =IFERROR(__xludf.DUMMYFUNCTION("""COMPUTED_VALUE"""),"M") -> M | C19: =IFERROR(__xludf.DUMMYFUNCTION("""COMPUTED_VALUE"""),2.0) -> 2
A20: =IFERROR(__xludf.DUMMYFUNCTION("""COMPUTED_VALUE"""),"102") -> 102 | B20: =IFERROR(__xludf.DUMMYFUNCTION("""COMPUTED_VALUE"""),"XXXL") -> XXXL | C20: =IFERROR(__xludf.DUMMYFUNCTION("""COMPUTED_VALUE"""),3.0) -> 3
A21: =IFERROR(__xludf.DUMMYFUNCTION("""COMPUTED_VALUE"""),"103") -> 103 | B21: =IFERROR(__xludf.DUMMYFUNCTION("""COMPUTED_VALUE"""),"M") -> M | C21: =IFERROR(__xludf.DUMMYFUNCTION("""COMPUTED_VALUE"""),3.0) -> 3
A22: =IFERROR(__xludf.DUMMYFUNCTION("""COMPUTED_VALUE"""),"109") -> 109 | B22: =IFERROR(__xludf.DUMMYFUNCTION("""COMPUTED_VALUE"""),"M") -> M | C22: =IFERROR(__xludf.DUMMYFUNCTION("""COMPUTED_VALUE"""),2.0) -> 2
A23: =IFERROR(__xludf.DUMMYFUNCTION("""COMPUTED_VALUE"""),"110") -> 110 | B23: =IFERROR(__xludf.DUMMYFUNCTION("""COMPUTED_VALUE"""),"M") -> M | C23: =IFERROR(__xludf.DUMMYFUNCTION("""COMPUTED_VALUE"""),3.0) -> 3
A24: =IFERROR(__xludf.DUMMYFUNCTION("""COMPUTED_VALUE"""),"111") -> 111 | B24: =IFERROR(__xludf.DUMMYFUNCTION("""COMPUTED_VALUE"""),"S") -> S | C24: =IFERROR(__xludf.DUMMYFUNCTION("""COMPUTED_VALUE"""),1.0) -> 1
A25: =IFERROR(__xludf.DUMMYFUNCTION("""COMPUTED_VALUE"""),"117") -> 117 | B25: =IFERROR(__xludf.DUMMYFUNCTION("""COMPUTED_VALUE"""),"M") -> M | C25: =IFERROR(__xludf.DUMMYFUNCTION("""COMPUTED_VALUE"""),3.0) -> 3
A26: =IFERROR(__xludf.DUMMYFUNCTION("""COMPUTED_VALUE"""),"118") -> 118 | B26: =IFERROR(__xludf.DUMMYFUNCTION("""COMPUTED_VALUE"""),"L") -> L | C26: =IFERROR(__xludf.DUMMYFUNCTION("""COMPUTED_VALUE"""),3.0) -> 3
A27: =IFERROR(__xludf.DUMMYFUNCTION("""COMPUTED_VALUE"""),"122") -> 122 | B27: =IFERROR(__xludf.DUMMYFUNCTION("""COMPUTED_VALUE"""),"M") -> M | C27: =IFERROR(__xludf.DUMMYFUNCTION("""COMPUTED_VALUE"""),2.0) -> 2
A28: =IFERROR(__xludf.DUMMYFUNCTION("""COMPUTED_VALUE"""),"129") -> 129 | B28: =IFERROR(__xludf.DUMMYFUNCTION("""COMPUTED_VALUE"""),"M") -> M | C28: =IFERROR(__xludf.DUMMYFUNCTION("""COMPUTED_VALUE"""),1.0) -> 1
A29: =IFERROR(__xludf.DUMMYFUNCTION("""COMPUTED_VALUE"""),"130") -> 130 | B29: =IFERROR(__xludf.DUMMYFUNCTION("""COMPUTED_VALUE"""),"S") -> S | C29: =IFERROR(__xludf.DUMMYFUNCTION("""COMPUTED_VALUE"""),3.0) -> 3
A30: =IFERROR(__xludf.DUMMYFUNCTION("""COMPUTED_VALUE"""),"131") -> 131 | B30: =IFERROR(__xludf.DUMMYFUNCTION("""COMPUTED_VALUE"""),"S") -> S | C30: =IFERROR(__xludf.DUMMYFUNCTION("""COMPUTED_VALUE"""),2.0) -> 2
A31: =IFERROR(__xludf.DUMMYFUNCTION("""COMPUTED_VALUE"""),"167") -> 167 | B31: =IFERROR(__xludf.DUMMYFUNCTION("""COMPUTED_VALUE"""),"M") -> M | C31: =IFERROR(__xludf.DUMMYFUNCTION("""COMPUTED_VALUE"""),3.0) -> 3

Sheet AREAS DE LOCKER
A1: AREAS DE LOCKER
A2: VESTIDOR HOMBRES
A3: VESTIDOR MUJERES
A4: ADMINISTRACION

Sheet AREAS DE PROCESO
A1: Area de USO
A2: PROCESO
A3: MTTO
A4: VISITAS
A5: CENCOSUD

Sheet AREAS
A1: Area
A2: LYD
A3: DES
A4: LOG
A5: CAL
A6: MTTO
A7: SST
A8: TIC

Sheet TALLAS
A1: Talla
A2: M
A3: L
A4: S
A5: XXL
A6: XL
A7: XXXL
A8: XS
A9: S-M-L-XL

Sheet LOCKER DISPONIBLES
A1: AREA | B1: # LOCKER | C1: AREAS DE LOCKER
A2: =IFERROR(__xludf.DUMMYFUNCTION("FILTER(LOCKERES!$A:$A,LOCKERES!$D:$D=""LOCKERT DISPONIBLE"")"),"DES") -> DES | B2: =IFERROR(__xludf.DUMMYFUNCTION("FILTER(LOCKERES!$B:$B,LOCKERES!$D:$D=""LOCKERT DISPONIBLE"")"),"DES-04") -> DES-04 | C2: =IFERROR(__xludf.DUMMYFUNCTION("FILTER(LOCKERES!$C:$C,LOCKERES!$D:$D=""LOCKERT DISPONIBLE"")"),"VESTIDOR HOMBRES") -> VESTIDOR HOMBRES
A3: =IFERROR(__xludf.DUMMYFUNCTION("""COMPUTED_VALUE"""),"DES") -> DES | B3: =IFERROR(__xludf.DUMMYFUNCTION("""COMPUTED_VALUE"""),"DES-08") -> DES-08 | C3: =IFERROR(__xludf.DUMMYFUNCTION("""COMPUTED_VALUE"""),"VESTIDOR HOMBRES") -> VESTIDOR HOMBRES
A4: =IFERROR(__xludf.DUMMYFUNCTION("""COMPUTED_VALUE"""),"DES") -> DES | B4: =IFERROR(__xludf.DUMMYFUNCTION("""COMPUTED_VALUE"""),"DES-09") -> DES-09 | C4: =IFERROR(__xludf.DUMMYFUNCTION("""COMPUTED_VALUE"""),"VESTIDOR HOMBRES") -> VESTIDOR HOMBRES
A5: =IFERROR(__xludf.DUMMYFUNCTION("""COMPUTED_VALUE"""),"DES") -> DES | B5: =IFERROR(__xludf.DUMMYFUNCTION("""COMPUTED_VALUE"""),"DES-10") -> DES-10 | C5: =IFERROR(__xludf.DUMMYFUNCTION("""COMPUTED_VALUE"""),"VESTIDOR HOMBRES") -> VESTIDOR HOMBRES
A6: =IFERROR(__xludf.DUMMYFUNCTION("""COMPUTED_VALUE"""),"DES") -> DES | B6: =IFERROR(__xludf.DUMMYFUNCTION("""COMPUTED_VALUE"""),"DES-15") -> DES-15 | C6: =IFERROR(__xludf.DUMMYFUNCTION("""COMPUTED_VALUE"""),"VESTIDOR HOMBRES") -> VESTIDOR HOMBRES
A7: =IFERROR(__xludf.DUMMYFUNCTION("""COMPUTED_VALUE"""),"DES") -> DES | B7: =IFERROR(__xludf.DUMMYFUNCTION("""COMPUTED_VALUE"""),"DES-16") -> DES-16 | C7: =IFERROR(__xludf.DUMMYFUNCTION("""COMPUTED_VALUE"""),"VESTIDOR HOMBRES") -> VESTIDOR HOMBRES
A8: =IFERROR(__xludf.DUMMYFUNCTION("""COMPUTED_VALUE"""),"DES") -> DES | B8: =IFERROR(__xludf.DUMMYFUNCTION("""COMPUTED_VALUE"""),"DES-19") -> DES-19 | C8: =IFERROR(__xludf.DUMMYFUNCTION("""COMPUTED_VALUE"""),"VESTIDOR HOMBRES") -> VESTIDOR HOMBRES
A9: =IFERROR(__xludf.DUMMYFUNCTION("""COMPUTED_VALUE"""),"DES") -> DES | B9: =IFERROR(__xludf.DUMMYFUNCTION("""COMPUTED_VALUE"""),"DES-20") -> DES-20 | C9: =IFERROR(__xludf.DUMMYFUNCTION("""COMPUTED_VALUE"""),"VESTIDOR HOMBRES") -> VESTIDOR HOMBRES
A10: =IFERROR(__xludf.DUMMYFUNCTION("""COMPUTED_VALUE"""),"DES") -> DES | B10: =IFERROR(__xludf.DUMMYFUNCTION("""COMPUTED_VALUE"""),"DES-21") -> DES-21 | C10: =IFERROR(__xludf.DUMMYFUNCTION("""COMPUTED_VALUE"""),"VESTIDOR HOMBRES") -> VESTIDOR HOMBRES
A11: =IFERROR(__xludf.DUMMYFUNCTION("""COMPUTED_VALUE"""),"DES") -> DES | B11: =IFERROR(__xludf.DUMMYFUNCTION("""COMPUTED_VALUE"""),"DES-24") -> DES-24 | C11: =IFERROR(__xludf.DUMMYFUNCTION("""COMPUTED_VALUE"""),"VESTIDOR HOMBRES") -> VESTIDOR HOMBRES
A12: =IFERROR(__xludf.DUMMYFUNCTION("""COMPUTED_VALUE"""),"DES") -> DES | B12: =IFERROR(__xludf.DUMMYFUNCTION("""COMPUTED_VALUE"""),"DES-26") -> DES-26 | C12: =IFERROR(__xludf.DUMMYFUNCTION("""COMPUTED_VALUE"""),"VESTIDOR HOMBRES") -> VESTIDOR HOMBRES
A13: =IFERROR(__xludf.DUMMYFUNCTION("""COMPUTED_VALUE"""),"DES") -> DES | B13: =IFERROR(__xludf.DUMMYFUNCTION("""COMPUTED_VALUE"""),"DES-27") -> DES-27 | C13: =IFERROR(__xludf.DUMMYFUNCTION("""COMPUTED_VALUE"""),"VESTIDOR HOMBRES") -> VESTIDOR HOMBRES
A14: =IFERROR(__xludf.DUMMYFUNCTION("""COMPUTED_VALUE"""),"DES") -> DES | B14: =IFERROR(__xludf.DUMMYFUNCTION("""COMPUTED_VALUE"""),"DES-30") -> DES-30 | C14: =IFERROR(__xludf.DUMMYFUNCTION("""COMPUTED_VALUE"""),"VESTIDOR HOMBRES") -> VESTIDOR HOMBRES
A15: =IFERROR(__xludf.DUMMYFUNCTION("""COMPUTED_VALUE"""),"DES") -> DES | B15: =IFERROR(__xludf.DUMMYFUNCTION("""COMPUTED_VALUE"""),"DES-32") -> DES-32 | C15: =IFERROR(__xludf.DUMMYFUNCTION("""COMPUTED_VALUE"""),"VESTIDOR HOMBRES") -> VESTIDOR HOMBRES
A16: =IFERROR(__xludf.DUMMYFUNCTION("""COMPUTED_VALUE"""),"LOG") -> LOG | B16: =IFERROR(__xludf.DUMMYFUNCTION("""COMPUTED_VALUE"""),"LOG-01") -> LOG-01 | C16: =IFERROR(__xludf.DUMMYFUNCTION("""COMPUTED_VALUE"""),"VESTIDOR HOMBRES") -> VESTIDOR HOMBRES
A17: =IFERROR(__xludf.DUMMYFUNCTION("""COMPUTED_VALUE"""),"LOG") -> LOG | B17: =IFERROR(__xludf.DUMMYFUNCTION("""COMPUTED_VALUE"""),"LOG-04") -> LOG-04 | C17: =IFERROR(__xludf.DUMMYFUNCTION("""COMPUTED_VALUE"""),"VESTIDOR HOMBRES") -> VESTIDOR HOMBRES
A18: =IFERROR(__xludf.DUMMYFUNCTION("""COMPUTED_VALUE"""),"LOG") -> LOG | B18: =IFERROR(__xludf.DUMMYFUNCTION("""COMPUTED_VALUE"""),"LOG-05") -> LOG-05 | C18: =IFERROR(__xludf.DUMMYFUNCTION("""COMPUTED_VALUE"""),"VESTIDOR HOMBRES") -> VESTIDOR HOMBRES
A19: =IFERROR(__xludf.DUMMYFUNCTION("""COMPUTED_VALUE"""),"LOG") -> LOG | B19: =IFERROR(__xludf.DUMMYFUNCTION("""COMPUTED_VALUE"""),"LOG-06") -> LOG-06 | C19: =IFERROR(__xludf.DUMMYFUNCTION("""COMPUTED_VALUE"""),"VESTIDOR HOMBRES") -> VESTIDOR HOMBRES
A20: =IFERROR(__xludf.DUMMYFUNCTION("""COMPUTED_VALUE"""),"LOG") -> LOG | B20: =IFERROR(__xludf.DUMMYFUNCTION("""COMPUTED_VALUE"""),"LOG-07") -> LOG-07 | C20: =IFERROR(__xludf.DUMMYFUNCTION("""COMPUTED_VALUE"""),"VESTIDOR HOMBRES") -> VESTIDOR HOMBRES
A21: =IFERROR(__xludf.DUMMYFUNCTION("""COMPUTED_VALUE"""),"LOG") -> LOG | B21: =IFERROR(__xludf.DUMMYFUNCTION("""COMPUTED_VALUE"""),"LOG-09") -> LOG-09 | C21: =IFERROR(__xludf.DUMMYFUNCTION("""COMPUTED_VALUE"""),"VESTIDOR HOMBRES") -> VESTIDOR HOMBRES
A22: =IFERROR(__xludf.DUMMYFUNCTION("""COMPUTED_VALUE"""),"CAL") -> CAL | B22: =IFERROR(__xludf.DUMMYFUNCTION("""COMPUTED_VALUE"""),"CAL-01") -> CAL-01 | C22: =IFERROR(__xludf.DUMMYFUNCTION("""COMPUTED_VALUE"""),"VESTIDOR HOMBRES") -> VESTIDOR HOMBRES
A23: =IFERROR(__xludf.DUMMYFUNCTION("""COMPUTED_VALUE"""),"CAL") -> CAL | B23: =IFERROR(__xludf.DUMMYFUNCTION("""COMPUTED_VALUE"""),"CAL-02") -> CAL-02 | C23: =IFERROR(__xludf.DUMMYFUNCTION("""COMPUTED_VALUE"""),"VESTIDOR HOMBRES") -> VESTIDOR HOMBRES
A24: =IFERROR(__xludf.DUMMYFUNCTION("""COMPUTED_VALUE"""),"CAL") -> CAL | B24: =IFERROR(__xludf.DUMMYFUNCTION("""COMPUTED_VALUE"""),"CAL-03") -> CAL-03 | C24: =IFERROR(__xludf.DUMMYFUNCTION("""COMPUTED_VALUE"""),"VESTIDOR HOMBRES") -> VESTIDOR HOMBRES
A25: =IFERROR(__xludf.DUMMYFUNCTION("""COMPUTED_VALUE"""),"CAL") -> CAL | B25: =IFERROR(__xludf.DUMMYFUNCTION("""COMPUTED_VALUE"""),"CAL-04") -> CAL-04 | C25: =IFERROR(__xludf.DUMMYFUNCTION("""COMPUTED_VALUE"""),"VESTIDOR HOMBRES") -> VESTIDOR HOMBRES
A26: =IFERROR(__xludf.DUMMYFUNCTION("""COMPUTED_VALUE"""),"TIC") -> TIC | B26: =IFERROR(__xludf.DUMMYFUNCTION("""COMPUTED_VALUE"""),"TIC-01") -> TIC-01 | C26: =IFERROR(__xludf.DUMMYFUNCTION("""COMPUTED_VALUE"""),"VESTIDOR HOMBRES") -> VESTIDOR HOMBRES
A27: =IFERROR(__xludf.DUMMYFUNCTION("""COMPUTED_VALUE"""),"SST") -> SST | B27: =IFERROR(__xludf.DUMMYFUNCTION("""COMPUTED_VALUE"""),"SST-01") -> SST-01 | C27: =IFERROR(__xludf.DUMMYFUNCTION("""COMPUTED_VALUE"""),"VESTIDOR HOMBRES") -> VESTIDOR HOMBRES
A28: =IFERROR(__xludf.DUMMYFUNCTION("""COMPUTED_VALUE"""),"LYD") -> LYD | B28: =IFERROR(__xludf.DUMMYFUNCTION("""COMPUTED_VALUE"""),"LYD-01") -> LYD-01 | C28: =IFERROR(__xludf.DUMMYFUNCTION("""COMPUTED_VALUE"""),"VESTIDOR HOMBRES") -> VESTIDOR HOMBRES
A29: =IFERROR(__xludf.DUMMYFUNCTION("""COMPUTED_VALUE"""),"LYD") -> LYD | B29: =IFERROR(__xludf.DUMMYFUNCTION("""COMPUTED_VALUE"""),"LYD-02") -> LYD-02 | C29: =IFERROR(__xludf.DUMMYFUNCTION("""COMPUTED_VALUE"""),"VESTIDOR HOMBRES") -> VESTIDOR HOMBRES
A30: =IFERROR(__xludf.DUMMYFUNCTION("""COMPUTED_VALUE"""),"EXT") -> EXT | B30: =IFERROR(__xludf.DUMMYFUNCTION("""COMPUTED_VALUE"""),"EXT-01") -> EXT-01 | C30: =IFERROR(__xludf.DUMMYFUNCTION("""COMPUTED_VALUE"""),"VESTIDOR HOMBRES") -> VESTIDOR HOMBRES
A31: =IFERROR(__xludf.DUMMYFUNCTION("""COMPUTED_VALUE"""),"DES") -> DES | B31: =IFERROR(__xludf.DUMMYFUNCTION("""COMPUTED_VALUE"""),"DES-43") -> DES-43 | C31: =IFERROR(__xludf.DUMMYFUNCTION("""COMPUTED_VALUE"""),"VESTIDOR MUJERES") -> VESTIDOR MUJERES
A32: =IFERROR(__xludf.DUMMYFUNCTION("""COMPUTED_VALUE"""),"DES") -> DES | B32: =IFERROR(__xludf.DUMMYFUNCTION("""COMPUTED_VALUE"""),"DES-2") -> DES-2 | C32: =IFERROR(__xludf.DUMMYFUNCTION("""COMPUTED_VALUE"""),"VESTIDOR MUJERES") -> VESTIDOR MUJERES
A33: =IFERROR(__xludf.DUMMYFUNCTION("""COMPUTED_VALUE"""),"CAL") -> CAL | B33: =IFERROR(__xludf.DUMMYFUNCTION("""COMPUTED_VALUE"""),"CAL-01") -> CAL-01 | C33: =IFERROR(__xludf.DUMMYFUNCTION("""COMPUTED_VALUE"""),"ADMINISTRACION") -> ADMINISTRACION
A34: =IFERROR(__xludf.DUMMYFUNCTION("""COMPUTED_VALUE"""),"CAL") -> CAL | B34: =IFERROR(__xludf.DUMMYFUNCTION("""COMPUTED_VALUE"""),"CAL-02") -> CAL-02 | C34: =IFERROR(__xludf.DUMMYFUNCTION("""COMPUTED_VALUE"""),"ADMINISTRACION") -> ADMINISTRACION
A35: =IFERROR(__xludf.DUMMYFUNCTION("""COMPUTED_VALUE"""),"CAL") -> CAL | B35: =IFERROR(__xludf.DUMMYFUNCTION("""COMPUTED_VALUE"""),"CAL-03") -> CAL-03 | C35: =IFERROR(__xludf.DUMMYFUNCTION("""COMPUTED_VALUE"""),"ADMINISTRACION") -> ADMINISTRACION
A36: =IFERROR(__xludf.DUMMYFUNCTION("""COMPUTED_VALUE"""),"CAL") -> CAL | B36: =IFERROR(__xludf.DUMMYFUNCTION("""COMPUTED_VALUE"""),"CAL-04") -> CAL-04 | C36: =IFERROR(__xludf.DUMMYFUNCTION("""COMPUTED_VALUE"""),"ADMINISTRACION") -> ADMINISTRACION
A37: =IFERROR(__xludf.DUMMYFUNCTION("""COMPUTED_VALUE"""),"CAL") -> CAL | B37: =IFERROR(__xludf.DUMMYFUNCTION("""COMPUTED_VALUE"""),"CAL-05") -> CAL-05 | C37: =IFERROR(__xludf.DUMMYFUNCTION("""COMPUTED_VALUE"""),"ADMINISTRACION") -> ADMINISTRACION
