Workbook
Name Area: PERSONAL!$L$3:$L$16
Name AreadeLockers: #REF!
Name DOTACION: #REF!
Name LOCKERT: #REF!
Name LOCKERT: #REF!
Name PERSONAL: PERSONAL!$J$3:$J$79
Name Talla: PERSONAL!$M$3:$M$9

Sheet ASIGNACIONES
A1: ID asignaciones | B1: Codigo de Dotacion | C1: Fecha de Entrega | D1: Operario | E1: Codigo de Lockets | F1: identificacion | G1: Codigo de Seca Botas | H1: Area | I1: Talla de Operarios | J1: Talla de dotacion asignada | K1: Area de Lockers | L1: Observaciones | M1: Imagen
F2: {=IFERROR(VLOOKUP($D2:$D864,PERSONAL!B:E,2,0),"")} | H2: {=IFERROR(VLOOKUP($D2:$D864,PERSONAL!B:F,3,0),"")} | I2: {=IFERROR(VLOOKUP($D2:$D864,PERSONAL!$B:$E,4,0),"")} | J2: {=IFERROR(VLOOKUP($B2:B864,DOTACIONES!$B:$E,3,0),"")} | K2: {=IFERROR(VLOOKUP($D2:$D864,PERSONAL!B:F,5,0),"")} | M2: {=IFERROR(VLOOKUP($D2:$D864,PERSONAL!B:G,6,0),"")}
A4: 12aafa9f | B4: 003 | C4: 44823 | D4: RIVERA COLMENARES JHON NEIDER | E4: 4 | F4: 1066093880 | G4: 1 PCC | H4: PCC | I4: S | J4: S | K4: VESTIDOR HOMBRES | M4: 0
A5: 12aafa9f | B5: 006 | C5: 44823 | D5: BARAJAS APARICIO FIDEL | E5: 4 | F5: 91223001 | G5: 1 LN | H5: LN | I5: M | J5: M | K5: VESTIDOR HOMBRES | M5: 0
A6: 12aafa9f | B6: 009 | C6: 44823 | D6: CORTES NINO YENSON ERNESTO | E6: 3 | F6: 91466133 | G6: 2 LN | H6: LN | I6: L | J6: L | K6: VESTIDOR HOMBRES | M6: 0
A7: 12aafa9f | B7: 013 | C7: 44823 | D7: PABON ARAQUE OCTAVIO | E7: 2 | F7: 91506805 | G7: 2 PCC | H7: PCC | I7: L | J7: L | K7: VESTIDOR HOMBRES | M7: 0
A8: b8b14227 | B8: 015 | C8: 44823 | D8: TOLOZA JAIMES CLEIVER ERMIDES | E8: 2 | F8: 1098700274 | G8: 5 LN | H8: LN | I8: M | J8: M | K8: VESTIDOR HOMBRES | M8: 0
A9: 12aafa9f | B9: 019 | C9: 44823 | D9: ROBLES BELEÑO RONALDO | E9: 8 | F9: 1098805526 | G9: 7 LN | H9: LN | I9: XL | J9: XL | K9: VESTIDOR HOMBRES | M9: 0
A11: f189684a | B11: 022 | C11: 44823 | D11: SUAREZ JAIMES ALBERTO | E11: 7 | F11: 91452758 | G11: 8 LN | H11: LN | I11: S | J11: S | K11: VESTIDOR HOMBRES | M11: 0
A12: 12aafa9f | B12: 025 | C12: 44823 | D12: CAMACHO DIAZ DIEGO | E12: 6 | F12: 1095813788 | G12: 9 LN | H12: LN | I12: M | J12: M | K12: VESTIDOR HOMBRES | M12: 0
A13: 12aafa9f | B13: 029 | C13: 44823 | D13: AFANADOR PINEDA NELSON | E13: 14 | F13: 1102368534 | G13: 10 LN | H13: LN | I13: S | J13: S | K13: VESTIDOR HOMBRES | M13: 0
A15: 12aafa9f | B15: 038 | C15: 44823 | D15: REYES SISA VICTOR ALFONSO | E15: 41 | F15: 1098741455 | G15: 3 PCC | H15: PCC | I15: L | J15: L | K15: VESTIDOR HOMBRES | M15: 0
A17: c471b06a | B17: 044 | C17: 44823 | D17: BAUTISTA CRUZ JOSE DANIEL | E17: 1 | F17: 1090520256 | G17: 6 LYD | H17: LYD | I17: M | J17: M | K17: VESTIDOR HOMBRES | M17: 0
A18: 9bf1ecfd | B18: 047 | C18: 44823 | D18: AMADOR SUAN SIXTO | E18: 13 | F18: 91258301 | G18: 7 PCC | H18: PCC | I18: M | J18: M | K18: VESTIDOR HOMBRES | M18: 0
A19: 7648d8e2 | B19: 049 | C19: 44823 | D19: GUERRERO RAMOS LUIS DAVID | E19: 20 | F19: 1098770376 | G19: 9 PCC | H19: PCC | I19: L | J19: L | K19: VESTIDOR HOMBRES | M19: 0
A21: e31b802a | B21: 054 | C21: 44823 | D21: PEREZ ZORRILLA ELVER ANDRES | E21: 9 | F21: 1102375619 | G21: 2 ADM | H21: CAL | I21: XL | J21: XL | K21: ADMINISTRACION | M21: 0
A22: 12aafa9f | B22: 055 | C22: 44823 | D22: CORREA MANRIQUE LEONARDO | E22: 5 | F22: 1100891753 | G22: 7 LYD | H22: LYD | I22: L | J22: L | K22: VESTIDOR HOMBRES | M22: 0
A23: 12aafa9f | B23: 058 | C23: 44823 | D23: CARDENAS CAICEDO URIEL | E23: 19 | F23: 13748778 | G23: 14 LN | H23: LN | I23: M | J23: M | K23: VESTIDOR HOMBRES | M23: 0
... A32: 199f3bba | B32: 078 | C32: 44823 | D32: IBARRA MOLINA JEAN CARLOS | E32: 25 | F32: 1100976668 | G32: 19 LN | H32: LN | I32: M | J32: M | K32: VESTIDOR HOMBRES | M32: 0
A33: e7d3d6ec | B33: 079 | C33: 44823 | D33: DERIVADOS CARNICOS | E33: 1 | F33: N/A | H33: EXT | I33: M | J33: M | K33: VESTIDOR HOMBRES | M33: 0
A34: 12aafa9f | B34: 083 | C34: 44823 | D34: PACHECO MANRIQUE ANDRES FELIPE | E34: 30 | F34: 1005346356 | G34: 22 LN | H34: LN | I34: M | J34: M | K34: VESTIDOR HOMBRES | M34: 0
A37: 12aafa9f | B37: 088 | C37: 44823 | D37: SANCHEZ RODRIGUEZ EUDY JOSE | E37: 11 | F37: 8123448070 | G37: 4 LOG | H37: LOG | I37: L | J37: L | K37: VESTIDOR HOMBRES | M37: 0
A38: dd723b86 | B38: 090 | C38: 44823 | D38: CANCINO WILMAR JAVIER | E38: 21 | F38: 91347680 | G38: 23 LN | H38: LN | I38: XL | J38: XL | K38: VESTIDOR HOMBRES | M38: 0
A39: 1127947335 | B39: 096 | C39: 44823 | D39: RAMIREZ VARGAS OLINTO | E39: 34 | F39: 91176452 | G39: 24 LN | H39: LN | I39: L | J39: L | K39: VESTIDOR HOMBRES | M39: 0
A40: 12aafa9f | B40: 102 | C40: 44823 | D40: RUBIANO LEMUS YUDY ANDREA | E40: 16 | F40: 63560912 | G40: 3 MUJ | H40: CAL | I40: M | J40: M | K40: VESTIDOR MUJERES | M40: 0
A41: 12aafa9f | B41: 104 | C41: 44823 | D41: ARDILA SALAS EDWARD ALEXANDER | E41: 18 | F41: 1098645575 | G41: 9 LYD | H41: LYD | I41: L | J41: L | K41: VESTIDOR HOMBRES | M41: 0
A42: b0e3b29a | B42: 110 | C42: 44823 | D42: MANTILLA DELGADO LUIS ERNESTO | E42: 33 | F42: 91510509 | G42: 27 LN | H42: LN | I42: M | J42: M | K42: VESTIDOR HOMBRES | M42: 0
A43: 12aafa9f | B43: 116 | C43: 44823 | D43: SANDOVAL SUAREZ ELIANA YUDDYT | E43: 1 | F43: 37729142 | G43: 4 MUJ | H43: PCC | I43: M | J43: M | K43: VESTIDOR MUJERES | M43: 0
A44: 12aafa9f | B44: 117 | C44: 44823 | D44: LOPEZ JAIMES LEONARDO FABIO | E44: 28 | F44: 1097304486 | G44: 15 PCC | H44: PCC | I44: XL | J44: XL | K44: VESTIDOR HOMBRES | M44: 0
A45: 95db2cd4 | B45: 122 | C45: 44823 | D45: RINCON TORRES JAVIER ENRIQUE | E45: 29 | F45: 91185275 | G45: 16 PCC | H45: PCC | I45: XXL | J45: XXL | K45: VESTIDOR HOMBRES | M45: 0
A46: 12aafa9f | B46: 125 | C46: 44823 | D46: ESTUPIÑAN VELANDIA PEDRO FELIPE | E46: 19 | F46: 1104184702 | G46: 6 ADM | H46: CAL | I46: XXL | J46: XXL | K46: ADMINISTRACION | M46: 0
A47: 12aafa9f | B47: 130 | C47: 44823 | D47: GOMEZ GRATEROL JORGE ANDRES | E47: 14 | F47: 1140417725 | G47: 5 PCC | H47: PCC | I47: S | J47: M | K47: VESTIDOR HOMBRES | M47: 0
... A59: d1f6da20 | B59: 173 | C59: 44823 | D59: VERA BUITRAGO EDISON DAYAN | E59: 34 | F59: 91533211 | G59: 21 PCC | H59: PCC | I59: L | J59: L | K59: VESTIDOR HOMBRES | M59: 0
A61: f60a167b | B61: 214 | C61: 44823 | D61: DERIVADOS CARNICOS EDWIN ORDUZ | E61: 2 | F61: N/A | H61: EXT | I61: L | J61: L | K61: VESTIDOR HOMBRES | M61: 0
A62: 7a37178e | B62: 219 | C62: 44823 | D62: ASURCARNES BRAYAN HERRERA | E62: 3 | F62: N/A | G62: 13 ADM | H62: ASUR | I62: L | J62: L | K62: ADMINISTRACION | M62: 0
A63: 12aafa9f | B63: 228 | C63: 44823 | D63: AGON PEDRAZA JAIRO FABIAN | E63: 54 | F63: 1007679366 | G63: 25 PCC | H63: PCC | I63: M | J63: M | K63: VESTIDOR HOMBRES | M63: 0
A64: 12aafa9f | C64: 44823 | D64: OLIVERA FLORES JOSE GABRIEL | E64: 44 | F64: 72342162 | G64: 26 PCC | H64: PCC | I64: L | K64: VESTIDOR HOMBRES | M64: 0
A65: 6fc52de5 | B65: 233 | C65: 44823 | D65: CABALLERO MOTTA ELIAS | E65: 48 | F65: 5684958 | G65: 27 PCC | H65: PCC | I65: L | J65: L | K65: VESTIDOR HOMBRES | M65: 0
A66: 55c4d4cf | B66: 249 | C66: 44823 | D66: BETANCOURT AGUDELO LUZ JASMIN | E66: 9 | F66: 37557088 | G66: 9 MUJ | H66: PCC | I66: XL | J66: L | K66: VESTIDOR MUJERES | M66: 0
A67: 12aafa9f | B67: N/A | C67: 44823 | D67: MANTENIMIENTO | E67: 26 | F67: N/A | G67: 14 ADM | H67: MTTO | I67: S-M-L-XL | K67: ADMINISTRACION | M67: 0
...

Sheet LOCKERES
A1: Codigo de Lockets | B1: Area | C1: Area de Lockers | D1: ESTADO | E1: UNIDAD
A2: 16 | B2: ADM | C2: ADMINISTRACION | D2: =IF(B2="VIS","LOCKERT VISITA",IF(C2="VESTIDOR MUJERES",IF(COUNTIFS(ASIGNACIONES!E:E,A2,ASIGNACIONES!K:K,C2)=0,"LOCKERT DISPONIBLE","LOCKERT ASIGNADO"),IF(COUNTIFS(ASIGNACIONES!E:E,A2,ASIGNACIONES!H:H,B2,ASIGNACIONES!K:K,C2)=0,"LOCKERT DISPONIBLE","LOCKERT ASIGNADO"))) -> LOCKERT DISPONIBLE | E2: 1
A3: 27 | B3: ADM | C3: ADMINISTRACION | D3: =IF(B3="VIS","LOCKERT VISITA",IF(C3="VESTIDOR MUJERES",IF(COUNTIFS(ASIGNACIONES!E:E,A3,ASIGNACIONES!K:K,C3)=0,"LOCKERT DISPONIBLE","LOCKERT ASIGNADO"),IF(COUNTIFS(ASIGNACIONES!E:E,A3,ASIGNACIONES!H:H,B3,ASIGNACIONES!K:K,C3)=0,"LOCKERT DISPONIBLE","LOCKERT ASIGNADO"))) -> LOCKERT DISPONIBLE | E3: 1
A4: 1 | B4: ASUR | C4: ADMINISTRACION | D4: =IF(B4="VIS","LOCKERT VISITA",IF(C4="VESTIDOR MUJERES",IF(COUNTIFS(ASIGNACIONES!E:E,A4,ASIGNACIONES!K:K,C4)=0,"LOCKERT DISPONIBLE","LOCKERT ASIGNADO"),IF(COUNTIFS(ASIGNACIONES!E:E,A4,ASIGNACIONES!H:H,B4,ASIGNACIONES!K:K,C4)=0,"LOCKERT DISPONIBLE","LOCKERT ASIGNADO"))) -> LOCKERT DISPONIBLE | E4: 1
A5: 5 | B5: ASUR | C5: VESTIDOR MUJERES | D5: =IF(B5="VIS","LOCKERT VISITA",IF(C5="VESTIDOR MUJERES",IF(COUNTIFS(ASIGNACIONES!E:E,A5,ASIGNACIONES!K:K,C5)=0,"LOCKERT DISPONIBLE","LOCKERT ASIGNADO"),IF(COUNTIFS(ASIGNACIONES!E:E,A5,ASIGNACIONES!H:H,B5,ASIGNACIONES!K:K,C5)=0,"LOCKERT DISPONIBLE","LOCKERT ASIGNADO"))) -> LOCKERT DISPONIBLE | E5: 1
A6: 3 | B6: CAL | C6: ADMINISTRACION | D6: =IF(B6="VIS","LOCKERT VISITA",IF(C6="VESTIDOR MUJERES",IF(COUNTIFS(ASIGNACIONES!E:E,A6,ASIGNACIONES!K:K,C6)=0,"LOCKERT DISPONIBLE","LOCKERT ASIGNADO"),IF(COUNTIFS(ASIGNACIONES!E:E,A6,ASIGNACIONES!H:H,B6,ASIGNACIONES!K:K,C6)=0,"LOCKERT DISPONIBLE","LOCKERT ASIGNADO"))) -> LOCKERT DISPONIBLE | E6: 1
A7: 4 | B7: CAL | C7: VESTIDOR MUJERES | D7: =IF(B7="VIS","LOCKERT VISITA",IF(C7="VESTIDOR MUJERES",IF(COUNTIFS(ASIGNACIONES!E:E,A7,ASIGNACIONES!K:K,C7)=0,"LOCKERT DISPONIBLE","LOCKERT ASIGNADO"),IF(COUNTIFS(ASIGNACIONES!E:E,A7,ASIGNACIONES!H:H,B7,ASIGNACIONES!K:K,C7)=0,"LOCKERT DISPONIBLE","LOCKERT ASIGNADO"))) -> LOCKERT DISPONIBLE | E7: 1
A8: 6 | B8: MTTO | C8: ADMINISTRACION | D8: =IF(B8="VIS","LOCKERT VISITA",IF(C8="VESTIDOR MUJERES",IF(COUNTIFS(ASIGNACIONES!E:E,A8,ASIGNACIONES!K:K,C8)=0,"LOCKERT DISPONIBLE","LOCKERT ASIGNADO"),IF(COUNTIFS(ASIGNACIONES!E:E,A8,ASIGNACIONES!H:H,B8,ASIGNACIONES!K:K,C8)=0,"LOCKERT DISPONIBLE","LOCKERT ASIGNADO"))) -> LOCKERT ASIGNADO | E8: 1
A9: 8 | B9: CAL | C9: VESTIDOR MUJERES | D9: =IF(B9="VIS","LOCKERT VISITA",IF(C9="VESTIDOR MUJERES",IF(COUNTIFS(ASIGNACIONES!E:E,A9,ASIGNACIONES!K:K,C9)=0,"LOCKERT DISPONIBLE","LOCKERT ASIGNADO"),IF(COUNTIFS(ASIGNACIONES!E:E,A9,ASIGNACIONES!H:H,B9,ASIGNACIONES!K:K,C9)=0,"LOCKERT DISPONIBLE","LOCKERT ASIGNADO"))) -> LOCKERT ASIGNADO | E9: 1
A10: 9 | B10: CAL | C10: ADMINISTRACION | D10: =IF(B10="VIS","LOCKERT VISITA",IF(C10="VESTIDOR MUJERES",IF(COUNTIFS(ASIGNACIONES!E:E,A10,ASIGNACIONES!K:K,C10)=0,"LOCKERT DISPONIBLE","LOCKERT ASIGNADO"),IF(COUNTIFS(ASIGNACIONES!E:E,A10,ASIGNACIONES!H:H,B10,ASIGNACIONES!K:K,C10)=0,"LOCKERT DISPONIBLE","LOCKERT ASIGNADO"))) -> LOCKERT ASIGNADO | E10: 1
A11: 13 | B11: CAL | C11: ADMINISTRACION | D11: =IF(B11="VIS","LOCKERT VISITA",IF(C11="VESTIDOR MUJERES",IF(COUNTIFS(ASIGNACIONES!E:E,A11,ASIGNACIONES!K:K,C11)=0,"LOCKERT DISPONIBLE","LOCKERT ASIGNADO"),IF(COUNTIFS(ASIGNACIONES!E:E,A11,ASIGNACIONES!H:H,B11,ASIGNACIONES!K:K,C11)=0,"LOCKERT DISPONIBLE","LOCKERT ASIGNADO"))) -> LOCKERT ASIGNADO | E11: 1
A12: 14 | B12: CAL | C12: ADMINISTRACION | D12: =IF(B12="VIS","LOCKERT VISITA",IF(C12="VESTIDOR MUJERES",IF(COUNTIFS(ASIGNACIONES!E:E,A12,ASIGNACIONES!K:K,C12)=0,"LOCKERT DISPONIBLE","LOCKERT ASIGNADO"),IF(COUNTIFS(ASIGNACIONES!E:E,A12,ASIGNACIONES!H:H,B12,ASIGNACIONES!K:K,C12)=0,"LOCKERT DISPONIBLE","LOCKERT ASIGNADO"))) -> LOCKERT DISPONIBLE | E12: 1
A13: 19 | B13: CAL | C13: ADMINISTRACION | D13: =IF(B13="VIS","LOCKERT VISITA",IF(C13="VESTIDOR MUJERES",IF(COUNTIFS(ASIGNACIONES!E:E,A13,ASIGNACIONES!K:K,C13)=0,"LOCKERT DISPONIBLE","LOCKERT ASIGNADO"),IF(COUNTIFS(ASIGNACIONES!E:E,A13,ASIGNACIONES!H:H,B13,ASIGNACIONES!K:K,C13)=0,"LOCKERT DISPONIBLE","LOCKERT ASIGNADO"))) -> LOCKERT ASIGNADO | E13: 1
... A17: 29 | B17: CAL | C17: ADMINISTRACION | D17: =IF(B17="VIS","LOCKERT VISITA",IF(C17="VESTIDOR MUJERES",IF(COUNTIFS(ASIGNACIONES!E:E,A17,ASIGNACIONES!K:K,C17)=0,"LOCKERT DISPONIBLE","LOCKERT ASIGNADO"),IF(COUNTIFS(ASIGNACIONES!E:E,A17,ASIGNACIONES!H:H,B17,ASIGNACIONES!K:K,C17)=0,"LOCKERT DISPONIBLE","LOCKERT ASIGNADO"))) -> LOCKERT ASIGNADO | E17: 1
A18: 16 | B18: CAL | C18: VESTIDOR MUJERES | D18: =IF(B18="VIS","LOCKERT VISITA",IF(C18="VESTIDOR MUJERES",IF(COUNTIFS(ASIGNACIONES!E:E,A18,ASIGNACIONES!K:K,C18)=0,"LOCKERT DISPONIBLE","LOCKERT ASIGNADO"),IF(COUNTIFS(ASIGNACIONES!E:E,A18,ASIGNACIONES!H:H,B18,ASIGNACIONES!K:K,C18)=0,"LOCKERT DISPONIBLE","LOCKERT ASIGNADO"))) -> LOCKERT ASIGNADO | E18: 1
A19: 20 | B19: CAL | C19: VESTIDOR MUJERES | D19: =IF(B19="VIS","LOCKERT VISITA",IF(C19="VESTIDOR MUJERES",IF(COUNTIFS(ASIGNACIONES!E:E,A19,ASIGNACIONES!K:K,C19)=0,"LOCKERT DISPONIBLE","LOCKERT ASIGNADO"),IF(COUNTIFS(ASIGNACIONES!E:E,A19,ASIGNACIONES!H:H,B19,ASIGNACIONES!K:K,C19)=0,"LOCKERT DISPONIBLE","LOCKERT ASIGNADO"))) -> LOCKERT DISPONIBLE | E19: 1
A20: 3 | B20: CAL | C20: VESTIDOR MUJERES | D20: =IF(B20="VIS","LOCKERT VISITA",IF(C20="VESTIDOR MUJERES",IF(COUNTIFS(ASIGNACIONES!E:E,A20,ASIGNACIONES!K:K,C20)=0,"LOCKERT DISPONIBLE","LOCKERT ASIGNADO"),IF(COUNTIFS(ASIGNACIONES!E:E,A20,ASIGNACIONES!H:H,B20,ASIGNACIONES!K:K,C20)=0,"LOCKERT DISPONIBLE","LOCKERT ASIGNADO"))) -> LOCKERT ASIGNADO | E20: 1
A21: 9 | B21: CAL | C21: VESTIDOR MUJERES | D21: =IF(B21="VIS","LOCKERT VISITA",IF(C21="VESTIDOR MUJERES",IF(COUNTIFS(ASIGNACIONES!E:E,A21,ASIGNACIONES!K:K,C21)=0,"LOCKERT DISPONIBLE","LOCKERT ASIGNADO"),IF(COUNTIFS(ASIGNACIONES!E:E,A21,ASIGNACIONES!H:H,B21,ASIGNACIONES!K:K,C21)=0,"LOCKERT DISPONIBLE","LOCKERT ASIGNADO"))) -> LOCKERT ASIGNADO | E21: 1
A22: 1 | B22: EXT | C22: VESTIDOR HOMBRES | D22: =IF(B22="VIS","LOCKERT VISITA",IF(C22="VESTIDOR MUJERES",IF(COUNTIFS(ASIGNACIONES!E:E,A22,ASIGNACIONES!K:K,C22)=0,"LOCKERT DISPONIBLE","LOCKERT ASIGNADO"),IF(COUNTIFS(ASIGNACIONES!E:E,A22,ASIGNACIONES!H:H,B22,ASIGNACIONES!K:K,C22)=0,"LOCKERT DISPONIBLE","LOCKERT ASIGNADO"))) -> LOCKERT ASIGNADO | E22: 1
A23: 2 | B23: EXT | C23: VESTIDOR HOMBRES | D23: =IF(B23="VIS","LOCKERT VISITA",IF(C23="VESTIDOR MUJERES",IF(COUNTIFS(ASIGNACIONES!E:E,A23,ASIGNACIONES!K:K,C23)=0,"LOCKERT DISPONIBLE","LOCKERT ASIGNADO"),IF(COUNTIFS(ASIGNACIONES!E:E,A23,ASIGNACIONES!H:H,B23,ASIGNACIONES!K:K,C23)=0,"LOCKERT DISPONIBLE","LOCKERT ASIGNADO"))) -> LOCKERT ASIGNADO | E23: 1
A24: 3 | B24: EXT | C24: VESTIDOR HOMBRES | D24: =IF(B24="VIS","LOCKERT VISITA",IF(C24="VESTIDOR MUJERES",IF(COUNTIFS(ASIGNACIONES!E:E,A24,ASIGNACIONES!K:K,C24)=0,"LOCKERT DISPONIBLE","LOCKERT ASIGNADO"),IF(COUNTIFS(ASIGNACIONES!E:E,A24,ASIGNACIONES!H:H,B24,ASIGNACIONES!K:K,C24)=0,"LOCKERT DISPONIBLE","LOCKERT ASIGNADO"))) -> LOCKERT ASIGNADO | E24: 1
A25: 4 | B25: EXT | C25: VESTIDOR HOMBRES | D25: =IF(B25="VIS","LOCKERT VISITA",IF(C25="VESTIDOR MUJERES",IF(COUNTIFS(ASIGNACIONES!E:E,A25,ASIGNACIONES!K:K,C25)=0,"LOCKERT DISPONIBLE","LOCKERT ASIGNADO"),IF(COUNTIFS(ASIGNACIONES!E:E,A25,ASIGNACIONES!H:H,B25,ASIGNACIONES!K:K,C25)=0,"LOCKERT DISPONIBLE","LOCKERT ASIGNADO"))) -> LOCKERT ASIGNADO | E25: 1
A26: 4 | B26: EXT | C26: ADMINISTRACION | D26: =IF(B26="VIS","LOCKERT VISITA",IF(C26="VESTIDOR MUJERES",IF(COUNTIFS(ASIGNACIONES!E:E,A26,ASIGNACIONES!K:K,C26)=0,"LOCKERT DISPONIBLE","LOCKERT ASIGNADO"),IF(COUNTIFS(ASIGNACIONES!E:E,A26,ASIGNACIONES!H:H,B26,ASIGNACIONES!K:K,C26)=0,"LOCKERT DISPONIBLE","LOCKERT ASIGNADO"))) -> LOCKERT DISPONIBLE | E26: 1
A27: 5 | B27: EXT | C27: VESTIDOR HOMBRES | D27: =IF(B27="VIS","LOCKERT VISITA",IF(C27="VESTIDOR MUJERES",IF(COUNTIFS(ASIGNACIONES!E:E,A27,ASIGNACIONES!K:K,C27)=0,"LOCKERT DISPONIBLE","LOCKERT ASIGNADO"),IF(COUNTIFS(ASIGNACIONES!E:E,A27,ASIGNACIONES!H:H,B27,ASIGNACIONES!K:K,C27)=0,"LOCKERT DISPONIBLE","LOCKERT ASIGNADO"))) -> LOCKERT ASIGNADO | E27: 1
A28: 11 | B28: EXT | C28: ADMINISTRACION | D28: =IF(B28="VIS","LOCKERT VISITA",IF(C28="VESTIDOR MUJERES",IF(COUNTIFS(ASIGNACIONES!E:E,A28,ASIGNACIONES!K:K,C28)=0,"LOCKERT DISPONIBLE","LOCKERT ASIGNADO"),IF(COUNTIFS(ASIGNACIONES!E:E,A28,ASIGNACIONES!H:H,B28,ASIGNACIONES!K:K,C28)=0,"LOCKERT DISPONIBLE","LOCKERT ASIGNADO"))) -> LOCKERT DISPONIBLE | E28: 1
A29: 23 | B29: GG | C29: ADMINISTRACION | D29: =IF(B29="VIS","LOCKERT VISITA",IF(C29="VESTIDOR MUJERES",IF(COUNTIFS(ASIGNACIONES!E:E,A29,ASIGNACIONES!K:K,C29)=0,"LOCKERT DISPONIBLE","LOCKERT ASIGNADO"),IF(COUNTIFS(ASIGNACIONES!E:E,A29,ASIGNACIONES!H:H,B29,ASIGNACIONES!K:K,C29)=0,"LOCKERT DISPONIBLE","LOCKERT ASIGNADO"))) -> LOCKERT DISPONIBLE | E29: 1
A30: 1 | B30: LN | C30: VESTIDOR HOMBRES | D30: =IF(B30="VIS","LOCKERT VISITA",IF(C30="VESTIDOR MUJERES",IF(COUNTIFS(ASIGNACIONES!E:E,A30,ASIGNACIONES!K:K,C30)=0,"LOCKERT DISPONIBLE","LOCKERT ASIGNADO"),IF(COUNTIFS(ASIGNACIONES!E:E,A30,ASIGNACIONES!H:H,B30,ASIGNACIONES!K:K,C30)=0,"LOCKERT DISPONIBLE","LOCKERT ASIGNADO"))) -> LOCKERT ASIGNADO | E30: 1
A31: 2 | B31: LN | C31: VESTIDOR HOMBRES | D31: =IF(B31="VIS","LOCKERT VISITA",IF(C31="VESTIDOR MUJERES",IF(COUNTIFS(ASIGNACIONES!E:E,A31,ASIGNACIONES!K:K,C31)=0,"LOCKERT DISPONIBLE","LOCKERT ASIGNADO"),IF(COUNTIFS(ASIGNACIONES!E:E,A31,ASIGNACIONES!H:H,B31,ASIGNACIONES!K:K,C31)=0,"LOCKERT DISPONIBLE","LOCKERT ASIGNADO"))) -> LOCKERT ASIGNADO | E31: 1
A32: 3 | B32: LN | C32: VESTIDOR HOMBRES | D32: =IF(B32="VIS","LOCKERT VISITA",IF(C32="VESTIDOR MUJERES",IF(COUNTIFS(ASIGNACIONES!E:E,A32,ASIGNACIONES!K:K,C32)=0,"LOCKERT DISPONIBLE","LOCKERT ASIGNADO"),IF(COUNTIFS(ASIGNACIONES!E:E,A32,ASIGNACIONES!H:H,B32,ASIGNACIONES!K:K,C32)=0,"LOCKERT DISPONIBLE","LOCKERT ASIGNADO"))) -> LOCKERT ASIGNADO | E32: 1
A33: 4 | B33: LN | C33: VESTIDOR HOMBRES | D33: =IF(B33="VIS","LOCKERT VISITA",IF(C33="VESTIDOR MUJERES",IF(COUNTIFS(ASIGNACIONES!E:E,A33,ASIGNACIONES!K:K,C33)=0,"LOCKERT DISPONIBLE","LOCKERT ASIGNADO"),IF(COUNTIFS(ASIGNACIONES!E:E,A33,ASIGNACIONES!H:H,B33,ASIGNACIONES!K:K,C33)=0,"LOCKERT DISPONIBLE","LOCKERT ASIGNADO"))) -> LOCKERT ASIGNADO | E33: 1
... A146: 22 | B146: LYD | C146: VESTIDOR HOMBRES | D146: =IF(B146="VIS","LOCKERT VISITA",IF(C146="VESTIDOR MUJERES",IF(COUNTIFS(ASIGNACIONES!E:E,A146,ASIGNACIONES!K:K,C146)=0,"LOCKERT DISPONIBLE","LOCKERT ASIGNADO"),IF(COUNTIFS(ASIGNACIONES!E:E,A146,ASIGNACIONES!H:H,B146,ASIGNACIONES!K:K,C146)=0,"LOCKERT DISPONIBLE","LOCKERT ASIGNADO"))) -> LOCKERT DISPONIBLE | E146: 1
A147: 65 | B147: LN | C147: VESTIDOR HOMBRES | D147: =IF(B147="VIS","LOCKERT VISITA",IF(C147="VESTIDOR MUJERES",IF(COUNTIFS(ASIGNACIONES!E:E,A147,ASIGNACIONES!K:K,C147)=0,"LOCKERT DISPONIBLE","LOCKERT ASIGNADO"),IF(COUNTIFS(ASIGNACIONES!E:E,A147,ASIGNACIONES!H:H,B147,ASIGNACIONES!K:K,C147)=0,"LOCKERT DISPONIBLE","LOCKERT ASIGNADO"))) -> LOCKERT ASIGNADO | E147: 1
A148: 26 | B148: MTTO | C148: ADMINISTRACION | D148: =IF(B148="VIS","LOCKERT VISITA",IF(C148="VESTIDOR MUJERES",IF(COUNTIFS(ASIGNACIONES!E:E,A148,ASIGNACIONES!K:K,C148)=0,"LOCKERT DISPONIBLE","LOCKERT ASIGNADO"),IF(COUNTIFS(ASIGNACIONES!E:E,A148,ASIGNACIONES!H:H,B148,ASIGNACIONES!K:K,C148)=0,"LOCKERT DISPONIBLE","LOCKERT ASIGNADO"))) -> LOCKERT ASIGNADO | E148: 1
A149: 1 | B149: PCC | C149: VESTIDOR HOMBRES | D149: =IF(B149="VIS","LOCKERT VISITA",IF(C149="VESTIDOR MUJERES",IF(COUNTIFS(ASIGNACIONES!E:E,A149,ASIGNACIONES!K:K,C149)=0,"LOCKERT DISPONIBLE","LOCKERT ASIGNADO"),IF(COUNTIFS(ASIGNACIONES!E:E,A149,ASIGNACIONES!H:H,B149,ASIGNACIONES!K:K,C149)=0,"LOCKERT DISPONIBLE","LOCKERT ASIGNADO"))) -> LOCKERT ASIGNADO | E149: 1
A150: 1 | B150: PCC | C150: VESTIDOR MUJERES | D150: =IF(B150="VIS","LOCKERT VISITA",IF(C150="VESTIDOR MUJERES",IF(COUNTIFS(ASIGNACIONES!E:E,A150,ASIGNACIONES!K:K,C150)=0,"LOCKERT DISPONIBLE","LOCKERT ASIGNADO"),IF(COUNTIFS(ASIGNACIONES!E:E,A150,ASIGNACIONES!H:H,B150,ASIGNACIONES!K:K,C150)=0,"LOCKERT DISPONIBLE","LOCKERT ASIGNADO"))) -> LOCKERT ASIGNADO | E150: 1
A151: 2 | B151: PCC | C151: VESTIDOR HOMBRES | D151: =IF(B151="VIS","LOCKERT VISITA",IF(C151="VESTIDOR MUJERES",IF(COUNTIFS(ASIGNACIONES!E:E,A151,ASIGNACIONES!K:K,C151)=0,"LOCKERT DISPONIBLE","LOCKERT ASIGNADO"),IF(COUNTIFS(ASIGNACIONES!E:E,A151,ASIGNACIONES!H:H,B151,ASIGNACIONES!K:K,C151)=0,"LOCKERT DISPONIBLE","LOCKERT ASIGNADO"))) -> LOCKERT ASIGNADO | E151: 1
A152: 2 | B152: PCC | C152: VESTIDOR MUJERES | D152: =IF(B152="VIS","LOCKERT VISITA",IF(C152="VESTIDOR MUJERES",IF(COUNTIFS(ASIGNACIONES!E:E,A152,ASIGNACIONES!K:K,C152)=0,"LOCKERT DISPONIBLE","LOCKERT ASIGNADO"),IF(COUNTIFS(ASIGNACIONES!E:E,A152,ASIGNACIONES!H:H,B152,ASIGNACIONES!K:K,C152)=0,"LOCKERT DISPONIBLE","LOCKERT ASIGNADO"))) -> LOCKERT ASIGNADO | E152: 1
A153: 3 | B153: PCC | C153: VESTIDOR HOMBRES | D153: =IF(B153="VIS","LOCKERT VISITA",IF(C153="VESTIDOR MUJERES",IF(COUNTIFS(ASIGNACIONES!E:E,A153,ASIGNACIONES!K:K,C153)=0,"LOCKERT DISPONIBLE","LOCKERT ASIGNADO"),IF(COUNTIFS(ASIGNACIONES!E:E,A153,ASIGNACIONES!H:H,B153,ASIGNACIONES!K:K,C153)=0,"LOCKERT DISPONIBLE","LOCKERT ASIGNADO"))) -> LOCKERT ASIGNADO | E153: 1
A154: 4 | B154: PCC | C154: VESTIDOR HOMBRES | D154: =IF(B154="VIS","LOCKERT VISITA",IF(C154="VESTIDOR MUJERES",IF(COUNTIFS(ASIGNACIONES!E:E,A154,ASIGNACIONES!K:K,C154)=0,"LOCKERT DISPONIBLE","LOCKERT ASIGNADO"),IF(COUNTIFS(ASIGNACIONES!E:E,A154,ASIGNACIONES!H:H,B154,ASIGNACIONES!K:K,C154)=0,"LOCKERT DISPONIBLE","LOCKERT ASIGNADO"))) -> LOCKERT ASIGNADO | E154: 1
A155: 5 | B155: PCC | C155: VESTIDOR HOMBRES | D155: =IF(B155="VIS","LOCKERT VISITA",IF(C155="VESTIDOR MUJERES",IF(COUNTIFS(ASIGNACIONES!E:E,A155,ASIGNACIONES!K:K,C155)=0,"LOCKERT DISPONIBLE","LOCKERT ASIGNADO"),IF(COUNTIFS(ASIGNACIONES!E:E,A155,ASIGNACIONES!H:H,B155,ASIGNACIONES!K:K,C155)=0,"LOCKERT DISPONIBLE","LOCKERT ASIGNADO"))) -> LOCKERT DISPONIBLE | E155: 1
...

Sheet SECA BOTAS
A1: Codigo de Seca Botas | B1: Area de Lockers | C1: ESTADO | D1: UNIDAD
A2: 1 PCC | B2: VESTIDOR HOMBRES | C2: =IF(COUNTIFS(ASIGNACIONES!G:G,A2,ASIGNACIONES!K:K,B2)=0,"CODIGO DISPONIBLE","CODIGO ASIGNADO") -> CODIGO ASIGNADO | D2: 1
A3: 2 PCC | B3: VESTIDOR HOMBRES | C3: =IF(COUNTIFS(ASIGNACIONES!G:G,A3,ASIGNACIONES!K:K,B3)=0,"CODIGO DISPONIBLE","CODIGO ASIGNADO") -> CODIGO ASIGNADO | D3: 1
A4: 3 PCC | B4: VESTIDOR HOMBRES | C4: =IF(COUNTIFS(ASIGNACIONES!G:G,A4,ASIGNACIONES!K:K,B4)=0,"CODIGO DISPONIBLE","CODIGO ASIGNADO") -> CODIGO ASIGNADO | D4: 1
A5: 4 PCC | B5: VESTIDOR HOMBRES | C5: =IF(COUNTIFS(ASIGNACIONES!G:G,A5,ASIGNACIONES!K:K,B5)=0,"CODIGO DISPONIBLE","CODIGO ASIGNADO") -> CODIGO ASIGNADO | D5: 1
A6: 5 PCC | B6: VESTIDOR HOMBRES | C6: =IF(COUNTIFS(ASIGNACIONES!G:G,A6,ASIGNACIONES!K:K,B6)=0,"CODIGO DISPONIBLE","CODIGO ASIGNADO") -> CODIGO ASIGNADO | D6: 1
A7: 6 PCC | B7: VESTIDOR HOMBRES | C7: =IF(COUNTIFS(ASIGNACIONES!G:G,A7,ASIGNACIONES!K:K,B7)=0,"CODIGO DISPONIBLE","CODIGO ASIGNADO") -> CODIGO ASIGNADO | D7: 1
A8: 7 PCC | B8: VESTIDOR HOMBRES | C8: =IF(COUNTIFS(ASIGNACIONES!G:G,A8,ASIGNACIONES!K:K,B8)=0,"CODIGO DISPONIBLE","CODIGO ASIGNADO") -> CODIGO ASIGNADO | D8: 1
A9: 8 PCC | B9: VESTIDOR HOMBRES | C9: =IF(COUNTIFS(ASIGNACIONES!G:G,A9,ASIGNACIONES!K:K,B9)=0,"CODIGO DISPONIBLE","CODIGO ASIGNADO") -> CODIGO ASIGNADO | D9: 1
A10: 9 PCC | B10: VESTIDOR HOMBRES | C10: =IF(COUNTIFS(ASIGNACIONES!G:G,A10,ASIGNACIONES!K:K,B10)=0,"CODIGO DISPONIBLE","CODIGO ASIGNADO") -> CODIGO ASIGNADO | D10: 1
A11: 10 PCC | B11: VESTIDOR HOMBRES | C11: =IF(COUNTIFS(ASIGNACIONES!G:G,A11,ASIGNACIONES!K:K,B11)=0,"CODIGO DISPONIBLE","CODIGO ASIGNADO") -> CODIGO ASIGNADO | D11: 1
A12: 11 PCC | B12: VESTIDOR HOMBRES | C12: =IF(COUNTIFS(ASIGNACIONES!G:G,A12,ASIGNACIONES!K:K,B12)=0,"CODIGO DISPONIBLE","CODIGO ASIGNADO") -> CODIGO ASIGNADO | D12: 1
A13: 12 PCC | B13: VESTIDOR HOMBRES | C13: =IF(COUNTIFS(ASIGNACIONES!G:G,A13,ASIGNACIONES!K:K,B13)=0,"CODIGO DISPONIBLE","CODIGO ASIGNADO") -> CODIGO ASIGNADO | D13: 1
... A191: 16 MUJ | B191: VESTIDOR MUJERES | C191: =IF(COUNTIFS(ASIGNACIONES!G:G,A191,ASIGNACIONES!K:K,B191)=0,"CODIGO DISPONIBLE","CODIGO ASIGNADO") -> CODIGO ASIGNADO | D191: 1
C192: =IF(COUNTIFS(ASIGNACIONES!G:G,A192,ASIGNACIONES!K:K,B192)=0,"CODIGO DISPONIBLE","CODIGO ASIGNADO") -> CODIGO DISPONIBLE | D192: 1
C193: =IF(COUNTIFS(ASIGNACIONES!G:G,A193,ASIGNACIONES!K:K,B193)=0,"CODIGO DISPONIBLE","CODIGO ASIGNADO") -> CODIGO DISPONIBLE | D193: 1
C194: =IF(COUNTIFS(ASIGNACIONES!G:G,A194,ASIGNACIONES!K:K,B194)=0,"CODIGO DISPONIBLE","CODIGO ASIGNADO") -> CODIGO DISPONIBLE | D194: 1
C195: =IF(COUNTIFS(ASIGNACIONES!G:G,A195,ASIGNACIONES!K:K,B195)=0,"CODIGO DISPONIBLE","CODIGO ASIGNADO") -> CODIGO DISPONIBLE | D195: 1
C196: =IF(COUNTIFS(ASIGNACIONES!G:G,A196,ASIGNACIONES!K:K,B196)=0,"CODIGO DISPONIBLE","CODIGO ASIGNADO") -> CODIGO DISPONIBLE | D196: 1
C197: =IF(COUNTIFS(ASIGNACIONES!G:G,A197,ASIGNACIONES!K:K,B197)=0,"CODIGO DISPONIBLE","CODIGO ASIGNADO") -> CODIGO DISPONIBLE | D197: 1
C198: =IF(COUNTIFS(ASIGNACIONES!G:G,A198,ASIGNACIONES!K:K,B198)=0,"CODIGO DISPONIBLE","CODIGO ASIGNADO") -> CODIGO DISPONIBLE | D198: 1
C199: =IF(COUNTIFS(ASIGNACIONES!G:G,A199,ASIGNACIONES!K:K,B199)=0,"CODIGO DISPONIBLE","CODIGO ASIGNADO") -> CODIGO DISPONIBLE | D199: 1
C200: =IF(COUNTIFS(ASIGNACIONES!G:G,A200,ASIGNACIONES!K:K,B200)=0,"CODIGO DISPONIBLE","CODIGO ASIGNADO") -> CODIGO DISPONIBLE | D200: 1
C201: =IF(COUNTIFS(ASIGNACIONES!G:G,A201,ASIGNACIONES!K:K,B201)=0,"CODIGO DISPONIBLE","CODIGO ASIGNADO") -> CODIGO DISPONIBLE | D201: 1
C202: =IF(COUNTIFS(ASIGNACIONES!G:G,A202,ASIGNACIONES!K:K,B202)=0,"CODIGO DISPONIBLE","CODIGO ASIGNADO") -> CODIGO DISPONIBLE | D202: 1
C203: =IF(COUNTIFS(ASIGNACIONES!G:G,A203,ASIGNACIONES!K:K,B203)=0,"CODIGO DISPONIBLE","CODIGO ASIGNADO") -> CODIGO DISPONIBLE | D203: 1
... C224: =IF(COUNTIFS(ASIGNACIONES!G:G,A224,ASIGNACIONES!K:K,B224)=0,"CODIGO DISPONIBLE","CODIGO ASIGNADO") -> CODIGO DISPONIBLE | D224: 1
C225: =IF(COUNTIFS(ASIGNACIONES!G:G,A225,ASIGNACIONES!H:H,#REF!,ASIGNACIONES!K:K,B225)=0,"CODIGO DISPONIBLE","CODIGO ASIGNADO") -> CODIGO DISPONIBLE | D225: 1
C226: =IF(COUNTIFS(ASIGNACIONES!G:G,A226,ASIGNACIONES!H:H,#REF!,ASIGNACIONES!K:K,B226)=0,"CODIGO DISPONIBLE","CODIGO ASIGNADO") -> CODIGO DISPONIBLE | D226: 1
C227: =IF(COUNTIFS(ASIGNACIONES!G:G,A227,ASIGNACIONES!H:H,#REF!,ASIGNACIONES!K:K,B227)=0,"CODIGO DISPONIBLE","CODIGO ASIGNADO") -> CODIGO DISPONIBLE | D227: 1
C228: =IF(COUNTIFS(ASIGNACIONES!G:G,A228,ASIGNACIONES!H:H,#REF!,ASIGNACIONES!K:K,B228)=0,"CODIGO DISPONIBLE","CODIGO ASIGNADO") -> CODIGO DISPONIBLE | D228: 1
C229: =IF(COUNTIFS(ASIGNACIONES!G:G,A229,ASIGNACIONES!H:H,#REF!,ASIGNACIONES!K:K,B229)=0,"CODIGO DISPONIBLE","CODIGO ASIGNADO") -> CODIGO DISPONIBLE | D229: 1
C230: =IF(COUNTIFS(ASIGNACIONES!G:G,A230,ASIGNACIONES!H:H,#REF!,ASIGNACIONES!K:K,B230)=0,"CODIGO DISPONIBLE","CODIGO ASIGNADO") -> CODIGO DISPONIBLE | D230: 1
C231: =IF(COUNTIFS(ASIGNACIONES!G:G,A231,ASIGNACIONES!H:H,#REF!,ASIGNACIONES!K:K,B231)=0,"CODIGO DISPONIBLE","CODIGO ASIGNADO") -> CODIGO DISPONIBLE | D231: 1
C232: =IF(COUNTIFS(ASIGNACIONES!G:G,A232,ASIGNACIONES!K:K,B232)=0,"CODIGO DISPONIBLE","CODIGO ASIGNADO") -> CODIGO DISPONIBLE
C233: =IF(COUNTIFS(ASIGNACIONES!G:G,A233,ASIGNACIONES!K:K,B233)=0,"CODIGO DISPONIBLE","CODIGO ASIGNADO") -> CODIGO DISPONIBLE
C234: =IF(COUNTIFS(ASIGNACIONES!G:G,A234,ASIGNACIONES!K:K,B234)=0,"CODIGO DISPONIBLE","CODIGO ASIGNADO") -> CODIGO DISPONIBLE
C235: =IF(COUNTIFS(ASIGNACIONES!G:G,A235,ASIGNACIONES!K:K,B235)=0,"CODIGO DISPONIBLE","CODIGO ASIGNADO") -> CODIGO DISPONIBLE
C236: =IF(COUNTIFS(ASIGNACIONES!G:G,A236,ASIGNACIONES!K:K,B236)=0,"CODIGO DISPONIBLE","CODIGO ASIGNADO") -> CODIGO DISPONIBLE
C237: =IF(COUNTIFS(ASIGNACIONES!G:G,A237,ASIGNACIONES!K:K,B237)=0,"CODIGO DISPONIBLE","CODIGO ASIGNADO") -> CODIGO DISPONIBLE
...

Sheet RETIROS
A1: ID RETIRO | B1: identificacion | C1: Codigo de Dotacion | D1: Fecha de Retiro | E1: Operario | F1: Codigo de Lockets | G1: Area | H1: Talla de Operarios | I1: Talla de dotacion asignada | J1: Area de Lockers | K1: Observaciones | L1: Imagen | M1: Codigo de Seca Botas
A2: 5a8f7287 | B2: n/a | C2: 020 | D2: 45037 | E2: CASTILLO VIDES TANIA NICOL | F2: 7 | G2: SST | H2: M | I2: L | J2: VESTIDOR MUJERES
A3: 1cc5f3ea | B3: 1092389738 | C3: 171 | D3: 45037 | E3: CORVACHO RODRÍGUEZ CRISTHIAN ANDRÉS | F3: 56 | G3: LN | H3: M | I3: M | J3: VESTIDOR HOMBRES | K3: no realizo entrega formal
A4: 5a8f7286 | B4: 91512215 | C4: 188 | D4: 45037 | E4: RODRIGUEZ HERRERA NICOLAS | F4: 20 | G4: LOG | H4: L | I4: XL | J4: VESTIDOR HOMBRES | K4: Acendio a gestor en desposte
A5: 81fc02dd | B5: 91356514 | C5: 115 | D5: 45050 | E5: BARAJAS REY WILSON | F5: 26 | G5: LN | H5: M | I5: M | J5: VESTIDOR HOMBRES
A6: b2286812 | B6: 1096243133 | C6: 067 | D6: 45051 | E6: VIDES MARTINEZ KEVIN JUNNER | F6: 13 | G6: LOG | H6: L | I6: L | J6: VESTIDOR HOMBRES
A7: 3f3ba076 | B7: 1001815858 | C7: 107 | D7: 45054 | E7: DIAZ ROJAS DAVINSON | F7: 6 | G7: PCC | H7: M | I7: M | J7: VESTIDOR HOMBRES | K7: Retiro por Extraccion de calculos
A8: 0e81f7b9 | B8: 1099368102 | C8: 185 | D8: 45054 | E8: SANCHEZ BERNAL SAULO EDUARDO | F8: 32 | G8: PCC | H8: L | I8: L | J8: VESTIDOR HOMBRES | K8: Retiro por Extraccion de calculos
A9: 7157b2e8 | B9: 1098722582 | C9: 145 | D9: 45056 | E9: FONSECA SILVA LUDYN GABRIELA | F9: 10 | G9: SST | H9: M | I9: M | J9: VESTIDOR MUJERES
A10: 4ea1cc91 | B10: 1543684 | C10: 064 | D10: 45057 | E10: CORDERO YAGUARAN CHARLE | F10: 5 | G10: LN | H10: M | I10: L | J10: VESTIDOR HOMBRES
A11: 53edf475 | B11: 1095819172 | C11: 119 | D11: 45069 | E11: RODRIGUEZ MARTINEZ IVAN ANDRÉS | F11: 13 | G11: LOG | H11: L | I11: L | J11: VESTIDOR HOMBRES
A12: 8d791b9c | B12: 2677781 | C12: 017 | D12: 45082 | E12: NARVÁEZ RONDON DOUGLAS EZEQUIEL | F12: 16 | G12: PCC | H12: M | I12: S | J12: VESTIDOR HOMBRES | K12: Renuncia voluntaria
A13: 589f9cc8 | B13: 12503914 | C13: 126 | D13: 45083 | E13: NIÑO FRANKLIN MANUEL | F13: 56 | G13: PCC | H13: M | I13: M | J13: VESTIDOR HOMBRES | K13: Retiro bajo rendimiento
A14: 81c0de94 | B14: 1066083139 | C14: 261 | D14: 45090 | E14: BONILLA PACHECO ANDRES FELIPE | F14: 22 | G14: LN | H14: M | I14: M | J14: VESTIDOR HOMBRES
A15: 7ce70d61 | B15: 1101204999 | C15: 300 | D15: 45093 | E15: CARRERO RINCON GONZALO STIVEL | F15: 15 | G15: LOG | H15: M | I15: M | J15: VESTIDOR HOMBRES
A16: d98eb1ce | B16: 1007688229 | C16: 019 | D16: 45098 | E16: PORTELA MAÑARA OSMAIDER | F16: 21 | G16: PCC | H16: XL | I16: XL | J16: VESTIDOR HOMBRES | K16: Renuncia voluntaria
A17: 00cef8c6 | B17: 1007439705 | C17: 160 | D17: 45103 | E17: BELLO BLANCO BEURY ALEXANDER | F17: 5 | G17: PCC | H17: L | I17: L | J17: VESTIDOR HOMBRES | K17: Renuncia voluntaria
A18: ada44c4e | B18: 1005478935 | C18: 093 | D18: 45104 | E18: HERNANDEZ MARIÑO ANDELFO | F18: 21 | G18: PCC | H18: L | I18: L | J18: VESTIDOR HOMBRES | K18: Renuncia voluntaria (no trabajo)
A19: cbabbc6f | B19: 91232589 | C19: 176 | D19: 45107 | E19: QUINTERO PIMENTEL JORGE | F19: 23 | G19: GG | H19: L | I19: L | J19: ADMINISTRACION
A20: 81b5fc82 | B20: 1095825899 | C20: 200 | D20: 45108 | E20: LAMUS HERNANDEZ FABIO ALONSO | F20: 14 | G20: CAL | H20: M | I20: M | J20: ADMINISTRACION
A21: af7ac927 | B21: 1232892334 | C21: 061 | D21: 45111 | E21: PALOMINO MARULANDA BRAYAN JAVIER | F21: 19 | G21: LYD | H21: M | I21: M | J21: VESTIDOR HOMBRES
A22: c70b949a | B22: 1095907091 | C22: 126 | D22: 45112 | E22: BLANCO SEPULVEDA IVAN ANDRES | F22: 15 | G22: LOG | H22: M | I22: M | J22: VESTIDOR HOMBRES
A23: 72dafde4 | B23: 1047450497 | C23: 226 | D23: 45115 | E23: REYES GOMEZ RAFAEL EDUARDO | F23: 36 | G23: PCC | H23: M | I23: M | J23: VESTIDOR HOMBRES | K23: Renuncia voluntaria
A24: 9c2c4f65 | B24: 1098716949 | C24: 204 | D24: 45118 | E24: PINZÓN PEDRAZA GERZON ANDRÉS | F24: 41 | G24: LN | H24: M | I24: M | J24: VESTIDOR HOMBRES
A25: a601d765 | B25: 1005371766 | C25: 129 | D25: 45124 | E25: VALDERRAMA PINEDA KEVIN STEVEN | F25: 57 | G25: PCC | H25: M | I25: M | J25: VESTIDOR HOMBRES | K25: Renuncia voluntaria (bajo rendimiento, consumo de drogas)
A26: 9f5ef897 | B26: 1098807906 | C26: 030 | D26: 45126 | E26: CANONIGO ORTIZ JESSICA PAOLA | F26: 6 | G26: CAL | H26: S | I26: S | J26: VESTIDOR MUJERES
A27: 48c61bc5 | B27: 1098815659 | C27: 007 | D27: 45126 | E27: GUIZA HERRERA YULI KATHERINE | F27: 8 | G27: CAL | H27: M | I27: S | J27: VESTIDOR MUJERES
A28: c0a06ed3 | B28: 1005339880 | C28: 002 | D28: 45128 | E28: DIAZ CANTILLO SAMIR ANDRES | F28: 50 | G28: LN | H28: S | I28: M | J28: VESTIDOR HOMBRES
A29: 2d1edc8f | B29: 1101695854 | C29: 097 | D29: 45133 | E29: BENAVIDES PABA NAVIN LEONARDIS | F29: 31 | G29: PCC | H29: L | I29: L | J29: VESTIDOR HOMBRES | K29: Renuncia voluntaria
A30: 8ed5d5d4 | B30: 1005040763 | C30: 187 | D30: 45140 | E30: GALVIS GALVIS EVER MILCIADES | F30: 22 | G30: LN | H30: M | I30: M | J30: VESTIDOR HOMBRES
A31: b4d02fe0 | B31: 1100893628 | C31: 005 | D31: 45141 | E31: GUERRERO ALMEIDA CRISTIAN JAVIER | F31: 2 | G31: LOG | H31: M | I31: M | J31: VESTIDOR HOMBRES
A32: a439e3aa | B32: 1095932394 | C32: 019 | D32: 45146 | E32: PARADA ORTEGA GUSTAVO ADOLFO | F32: 15 | G32: LOG | H32: XL | I32: XL | J32: VESTIDOR HOMBRES
A33: a2a58866 | B33: 1065577704 | C33: S001 | D33: 45150 | E33: MOYA MUÑOZ JHON ALBERTO | F33: 51 | G33: PCC | H33: S | I33: S | J33: VESTIDOR HOMBRES | K33: Retiro bajo rendimiento
A34: faee112a | B34: 1129485327 | C34: 063 | D34: 45153 | E34: ARIZA MOLINA DEIVIS MANUEL | F34: 21 | G34: PCC | H34: M | I34: M | J34: VESTIDOR HOMBRES | K34: Renuncia voluntaria (cambio de ambiente)
A35: 89970959 | B35: 1098751464 | C35: 105 | D35: 45153 | E35: SEPULVEDA MANRIQUE MISAEL | F35: 22 | G35: PCC | H35: M | I35: M | J35: VESTIDOR HOMBRES | K35: Renuncia voluntaria
A36: d3aebb8e | B36: 1098618560 | C36: 139 | D36: 45154 | E36: ARAQUE HERRERA DIEGO JAVIER | F36: 16 | G36: LOG | H36: XL | I36: XL | J36: VESTIDOR HOMBRES
A37: 482a95f9 | B37: 1005650539 | C37: 007 | D37: 45154 | E37: BOHÓRQUEZ CORREDOR LENNIS TATIANA | F37: 8 | G37: CAL | H37: S | I37: S | J37: VESTIDOR MUJERES
A38: 0ed839a1 | B38: 1098660541 | C38: 005 | D38: 45154 | E38: PINZON RUEDA ERIN JOHAN | F38: 15 | G38: LOG | H38: M | I38: M | J38: VESTIDOR HOMBRES
A39: 5ab81d8c | B39: 1006822494 | C39: 264 | D39: 45154 | E39: VILLAMIZAR URBINA OMAR ANDRES | F39: 47 | G39: PCC | H39: L | I39: L | J39: VESTIDOR HOMBRES | K39: Retiro imcumplimiento de BPM
A40: 3c8e1c81 | B40: 1007769879 | C40: 012 | D40: 45157 | E40: DIAZ LIZARAZO JHIMMI FABIAN | F40: 44 | G40: LN | H40: M | I40: M | J40: VESTIDOR HOMBRES
...

Sheet PERSONAL
A1: ID PERSONAL | B1: Operario | C1: identificacion | D1: Area | E1: Talla | F1: Area de Lockers | G1: IMAGEN | H1: estado
H2: =IF($B2="","",IF($B2="TRANSCARNES","ACTIVO",IF(COUNTIF(RETIROS!E:E,$B2)=1,"PENDIENTE ELIMINAR",IF(COUNTIFS(ASIGNACIONES!$D:$D,$B2,ASIGNACIONES!$I:$I,E2,ASIGNACIONES!$H:$H,$D2,ASIGNACIONES!$K:$K,$F2)=0,"NUEVO","ACTIVO"))))
A3: 00d792fa | B3: BECERRA JAIMES DIEGO ARMANDO | C3: 1098724961 | D3: LN | E3: S | F3: VESTIDOR HOMBRES | H3: =IF($B3="","",IF($B3="TRANSCARNES","ACTIVO",IF(COUNTIF(RETIROS!E:E,$B3)=1,"PENDIENTE ELIMINAR",IF(COUNTIFS(ASIGNACIONES!$D:$D,$B3,ASIGNACIONES!$I:$I,E3,ASIGNACIONES!$H:$H,$D3,ASIGNACIONES!$K:$K,$F3)=0,"NUEVO","ACTIVO")))) -> ACTIVO
A4: 01142ded | B4: RODRIGUEZ LIZCANO EDINSON FERNEY | C4: 1099622755 | D4: CAL | E4: M | F4: VESTIDOR HOMBRES | H4: =IF($B4="","",IF($B4="TRANSCARNES","ACTIVO",IF(COUNTIF(RETIROS!E:E,$B4)=1,"PENDIENTE ELIMINAR",IF(COUNTIFS(ASIGNACIONES!$D:$D,$B4,ASIGNACIONES!$I:$I,E4,ASIGNACIONES!$H:$H,$D4,ASIGNACIONES!$K:$K,$F4)=0,"NUEVO","ACTIVO")))) -> ACTIVO
A5: 0464dd16 | B5: ASURCARNES JAVIER RINCON | C5: 1234 | D5: EXT | E5: M | F5: VESTIDOR HOMBRES | H5: =IF($B5="","",IF($B5="TRANSCARNES","ACTIVO",IF(COUNTIF(RETIROS!E:E,$B5)=1,"PENDIENTE ELIMINAR",IF(COUNTIFS(ASIGNACIONES!$D:$D,$B5,ASIGNACIONES!$I:$I,E5,ASIGNACIONES!$H:$H,$D5,ASIGNACIONES!$K:$K,$F5)=0,"NUEVO","ACTIVO")))) -> ACTIVO
A7: 09d054ef | B7: ANTON RODRÍGUEZ HECTOR LUIS | C7: 4588561 | D7: PCC | E7: L | F7: VESTIDOR HOMBRES | H7: =IF($B7="","",IF($B7="TRANSCARNES","ACTIVO",IF(COUNTIF(RETIROS!E:E,$B7)=1,"PENDIENTE ELIMINAR",IF(COUNTIFS(ASIGNACIONES!$D:$D,$B7,ASIGNACIONES!$I:$I,E7,ASIGNACIONES!$H:$H,$D7,ASIGNACIONES!$K:$K,$F7)=0,"NUEVO","ACTIVO")))) -> ACTIVO
A8: 0c4f0940 | B8: MANTENIMIENTO2 | C8: N/A | D8: MTTO | E8: S-M-L-XL | F8: ADMINISTRACION | H8: =IF($B8="","",IF($B8="TRANSCARNES","ACTIVO",IF(COUNTIF(RETIROS!E:E,$B8)=1,"PENDIENTE ELIMINAR",IF(COUNTIFS(ASIGNACIONES!$D:$D,$B8,ASIGNACIONES!$I:$I,E8,ASIGNACIONES!$H:$H,$D8,ASIGNACIONES!$K:$K,$F8)=0,"NUEVO","ACTIVO")))) -> ACTIVO
A10: 10 | B10: PACHECO MANRIQUE ANDRES FELIPE | C10: 1005346356 | D10: LN | E10: M | F10: VESTIDOR HOMBRES | H10: =IF($B10="","",IF($B10="TRANSCARNES","ACTIVO",IF(COUNTIF(RETIROS!E:E,$B10)=1,"PENDIENTE ELIMINAR",IF(COUNTIFS(ASIGNACIONES!$D:$D,$B10,ASIGNACIONES!$I:$I,E10,ASIGNACIONES!$H:$H,$D10,ASIGNACIONES!$K:$K,$F10)=0,"NUEVO","ACTIVO")))) -> ACTIVO
A11: 104 | B11: AGON PEDRAZA JAIRO FABIAN | C11: 1007679366 | D11: PCC | E11: M | F11: VESTIDOR HOMBRES | H11: =IF($B11="","",IF($B11="TRANSCARNES","ACTIVO",IF(COUNTIF(RETIROS!E:E,$B11)=1,"PENDIENTE ELIMINAR",IF(COUNTIFS(ASIGNACIONES!$D:$D,$B11,ASIGNACIONES!$I:$I,E11,ASIGNACIONES!$H:$H,$D11,ASIGNACIONES!$K:$K,$F11)=0,"NUEVO","ACTIVO")))) -> ACTIVO
A13: 107 | B13: IBARRA MOLINA JEAN CARLOS | C13: 1100976668 | D13: LN | E13: M | F13: VESTIDOR HOMBRES | H13: =IF($B13="","",IF($B13="TRANSCARNES","ACTIVO",IF(COUNTIF(RETIROS!E:E,$B13)=1,"PENDIENTE ELIMINAR",IF(COUNTIFS(ASIGNACIONES!$D:$D,$B13,ASIGNACIONES!$I:$I,E13,ASIGNACIONES!$H:$H,$D13,ASIGNACIONES!$K:$K,$F13)=0,"NUEVO","ACTIVO")))) -> ACTIVO
A14: 112 | B14: CARDENAS MELENDES JHON FREDY | C14: 91159389 | D14: LN | E14: L | F14: VESTIDOR HOMBRES | H14: =IF($B14="","",IF($B14="TRANSCARNES","ACTIVO",IF(COUNTIF(RETIROS!E:E,$B14)=1,"PENDIENTE ELIMINAR",IF(COUNTIFS(ASIGNACIONES!$D:$D,$B14,ASIGNACIONES!$I:$I,E14,ASIGNACIONES!$H:$H,$D14,ASIGNACIONES!$K:$K,$F14)=0,"NUEVO","ACTIVO")))) -> ACTIVO
A15: 113 | B15: MOGOLLON HERRENO JHON FREDY | C15: 1098706254 | D15: LN | E15: L | F15: VESTIDOR HOMBRES | H15: =IF($B15="","",IF($B15="TRANSCARNES","ACTIVO",IF(COUNTIF(RETIROS!E:E,$B15)=1,"PENDIENTE ELIMINAR",IF(COUNTIFS(ASIGNACIONES!$D:$D,$B15,ASIGNACIONES!$I:$I,E15,ASIGNACIONES!$H:$H,$D15,ASIGNACIONES!$K:$K,$F15)=0,"NUEVO","ACTIVO")))) -> ACTIVO
A17: 115 | B17: VARGAS OSSES JHON ELKIN | C17: 1012363759 | D17: LOG | E17: L | F17: VESTIDOR HOMBRES | H17: =IF($B17="","",IF($B17="TRANSCARNES","ACTIVO",IF(COUNTIF(RETIROS!E:E,$B17)=1,"PENDIENTE ELIMINAR",IF(COUNTIFS(ASIGNACIONES!$D:$D,$B17,ASIGNACIONES!$I:$I,E17,ASIGNACIONES!$H:$H,$D17,ASIGNACIONES!$K:$K,$F17)=0,"NUEVO","ACTIVO")))) -> ACTIVO
A19: 119 | B19: GOMEZ GRATEROL JORGE ANDRES | C19: 1140417725 | D19: PCC | E19: S | F19: VESTIDOR HOMBRES | H19: =IF($B19="","",IF($B19="TRANSCARNES","ACTIVO",IF(COUNTIF(RETIROS!E:E,$B19)=1,"PENDIENTE ELIMINAR",IF(COUNTIFS(ASIGNACIONES!$D:$D,$B19,ASIGNACIONES!$I:$I,E19,ASIGNACIONES!$H:$H,$D19,ASIGNACIONES!$K:$K,$F19)=0,"NUEVO","ACTIVO")))) -> ACTIVO
A20: 121 | B20: TORRES JORGE ELIECER | C20: 91294734 | D20: LYD | E20: M | F20: VESTIDOR HOMBRES | H20: =IF($B20="","",IF($B20="TRANSCARNES","ACTIVO",IF(COUNTIF(RETIROS!E:E,$B20)=1,"PENDIENTE ELIMINAR",IF(COUNTIFS(ASIGNACIONES!$D:$D,$B20,ASIGNACIONES!$I:$I,E20,ASIGNACIONES!$H:$H,$D20,ASIGNACIONES!$K:$K,$F20)=0,"NUEVO","ACTIVO")))) -> ACTIVO
A21: 124 | B21: BAUTISTA CRUZ JOSE DANIEL | C21: 1090520256 | D21: LYD | E21: M | F21: VESTIDOR HOMBRES | H21: =IF($B21="","",IF($B21="TRANSCARNES","ACTIVO",IF(COUNTIF(RETIROS!E:E,$B21)=1,"PENDIENTE ELIMINAR",IF(COUNTIFS(ASIGNACIONES!$D:$D,$B21,ASIGNACIONES!$I:$I,E21,ASIGNACIONES!$H:$H,$D21,ASIGNACIONES!$K:$K,$F21)=0,"NUEVO","ACTIVO")))) -> ACTIVO
A23: 139 | B23: CORREA MANRIQUE LEONARDO | C23: 1100891753 | D23: LYD | E23: L | F23: VESTIDOR HOMBRES | H23: =IF($B23="","",IF($B23="TRANSCARNES","ACTIVO",IF(COUNTIF(RETIROS!E:E,$B23)=1,"PENDIENTE ELIMINAR",IF(COUNTIFS(ASIGNACIONES!$D:$D,$B23,ASIGNACIONES!$I:$I,E23,ASIGNACIONES!$H:$H,$D23,ASIGNACIONES!$K:$K,$F23)=0,"NUEVO","ACTIVO")))) -> ACTIVO
A25: 141 | B25: LIZCANO MARTINEZ ISIDRO | C25: 91275933 | D25: PCC | E25: M | F25: VESTIDOR HOMBRES | H25: =IF($B25="","",IF($B25="TRANSCARNES","ACTIVO",IF(COUNTIF(RETIROS!E:E,$B25)=1,"PENDIENTE ELIMINAR",IF(COUNTIFS(ASIGNACIONES!$D:$D,$B25,ASIGNACIONES!$I:$I,E25,ASIGNACIONES!$H:$H,$D25,ASIGNACIONES!$K:$K,$F25)=0,"NUEVO","ACTIVO")))) -> ACTIVO
... A30: 150 | B30: MANTENIMIENTO | C30: N/A | D30: MTTO | E30: S-M-L-XL | F30: ADMINISTRACION | H30: =IF($B30="","",IF($B30="TRANSCARNES","ACTIVO",IF(COUNTIF(RETIROS!E:E,$B30)=1,"PENDIENTE ELIMINAR",IF(COUNTIFS(ASIGNACIONES!$D:$D,$B30,ASIGNACIONES!$I:$I,E30,ASIGNACIONES!$H:$H,$D30,ASIGNACIONES!$K:$K,$F30)=0,"NUEVO","ACTIVO")))) -> ACTIVO
A31: 15193dc6 | B31: PABON SERRANO ANDERSON | C31: 1091132817 | D31: LN | E31: M | F31: VESTIDOR HOMBRES | H31: =IF($B31="","",IF($B31="TRANSCARNES","ACTIVO",IF(COUNTIF(RETIROS!E:E,$B31)=1,"PENDIENTE ELIMINAR",IF(COUNTIFS(ASIGNACIONES!$D:$D,$B31,ASIGNACIONES!$I:$I,E31,ASIGNACIONES!$H:$H,$D31,ASIGNACIONES!$K:$K,$F31)=0,"NUEVO","ACTIVO")))) -> ACTIVO
A32: 152 | B32: MANZANO LIZARAZO MANZUR NAIN | C32: 1098718985 | D32: LYD | E32: XXL | F32: VESTIDOR HOMBRES | H32: =IF($B32="","",IF($B32="TRANSCARNES","ACTIVO",IF(COUNTIF(RETIROS!E:E,$B32)=1,"PENDIENTE ELIMINAR",IF(COUNTIFS(ASIGNACIONES!$D:$D,$B32,ASIGNACIONES!$I:$I,E32,ASIGNACIONES!$H:$H,$D32,ASIGNACIONES!$K:$K,$F32)=0,"NUEVO","ACTIVO")))) -> PENDIENTE ELIMINAR
A34: 154 | B34: ORDUZ SOLANO MARLON ALEXIS | C34: 1098743062 | D34: ADM | E34: L | F34: ADMINISTRACION | H34: =IF($B34="","",IF($B34="TRANSCARNES","ACTIVO",IF(COUNTIF(RETIROS!E:E,$B34)=1,"PENDIENTE ELIMINAR",IF(COUNTIFS(ASIGNACIONES!$D:$D,$B34,ASIGNACIONES!$I:$I,E34,ASIGNACIONES!$H:$H,$D34,ASIGNACIONES!$K:$K,$F34)=0,"NUEVO","ACTIVO")))) -> ACTIVO
A36: 15cae5f5 | B36: RIVERA GOMEZ CAMILO ANDRÉS | C36: 1001920490 | D36: PCC | E36: M | F36: VESTIDOR HOMBRES | H36: =IF($B36="","",IF($B36="TRANSCARNES","ACTIVO",IF(COUNTIF(RETIROS!E:E,$B36)=1,"PENDIENTE ELIMINAR",IF(COUNTIFS(ASIGNACIONES!$D:$D,$B36,ASIGNACIONES!$I:$I,E36,ASIGNACIONES!$H:$H,$D36,ASIGNACIONES!$K:$K,$F36)=0,"NUEVO","ACTIVO")))) -> ACTIVO
A37: 160 | B37: AFANADOR PINEDA NELSON | C37: 1102368534 | D37: LN | E37: S | F37: VESTIDOR HOMBRES | H37: =IF($B37="","",IF($B37="TRANSCARNES","ACTIVO",IF(COUNTIF(RETIROS!E:E,$B37)=1,"PENDIENTE ELIMINAR",IF(COUNTIFS(ASIGNACIONES!$D:$D,$B37,ASIGNACIONES!$I:$I,E37,ASIGNACIONES!$H:$H,$D37,ASIGNACIONES!$K:$K,$F37)=0,"NUEVO","ACTIVO")))) -> ACTIVO
A39: 163 | B39: RAMIREZ VARGAS OLINTO | C39: 91176452 | D39: LN | E39: L | F39: VESTIDOR HOMBRES | H39: =IF($B39="","",IF($B39="TRANSCARNES","ACTIVO",IF(COUNTIF(RETIROS!E:E,$B39)=1,"PENDIENTE ELIMINAR",IF(COUNTIFS(ASIGNACIONES!$D:$D,$B39,ASIGNACIONES!$I:$I,E39,ASIGNACIONES!$H:$H,$D39,ASIGNACIONES!$K:$K,$F39)=0,"NUEVO","ACTIVO")))) -> ACTIVO
A40: 164 | B40: OLIVERA FLORES JOSE GABRIEL | C40: 72342162 | D40: PCC | E40: L | F40: VESTIDOR HOMBRES | H40: =IF($B40="","",IF($B40="TRANSCARNES","ACTIVO",IF(COUNTIF(RETIROS!E:E,$B40)=1,"PENDIENTE ELIMINAR",IF(COUNTIFS(ASIGNACIONES!$D:$D,$B40,ASIGNACIONES!$I:$I,E40,ASIGNACIONES!$H:$H,$D40,ASIGNACIONES!$K:$K,$F40)=0,"NUEVO","ACTIVO")))) -> ACTIVO
A41: 168 | B41: PABON ARAQUE OCTAVIO | C41: 91506805 | D41: PCC | E41: L | F41: VESTIDOR HOMBRES | H41: =IF($B41="","",IF($B41="TRANSCARNES","ACTIVO",IF(COUNTIF(RETIROS!E:E,$B41)=1,"PENDIENTE ELIMINAR",IF(COUNTIFS(ASIGNACIONES!$D:$D,$B41,ASIGNACIONES!$I:$I,E41,ASIGNACIONES!$H:$H,$D41,ASIGNACIONES!$K:$K,$F41)=0,"NUEVO","ACTIVO")))) -> ACTIVO
A42: 169 | B42: ESTUPIÑAN VELANDIA PEDRO FELIPE | C42: 1104184702 | D42: CAL | E42: XXL | F42: ADMINISTRACION | H42: =IF($B42="","",IF($B42="TRANSCARNES","ACTIVO",IF(COUNTIF(RETIROS!E:E,$B42)=1,"PENDIENTE ELIMINAR",IF(COUNTIFS(ASIGNACIONES!$D:$D,$B42,ASIGNACIONES!$I:$I,E42,ASIGNACIONES!$H:$H,$D42,ASIGNACIONES!$K:$K,$F42)=0,"NUEVO","ACTIVO")))) -> ACTIVO
A44: 175 | B44: REYES SISA VICTOR ALFONSO | C44: 1098741455 | D44: PCC | E44: L | F44: VESTIDOR HOMBRES | H44: =IF($B44="","",IF($B44="TRANSCARNES","ACTIVO",IF(COUNTIF(RETIROS!E:E,$B44)=1,"PENDIENTE ELIMINAR",IF(COUNTIFS(ASIGNACIONES!$D:$D,$B44,ASIGNACIONES!$I:$I,E44,ASIGNACIONES!$H:$H,$D44,ASIGNACIONES!$K:$K,$F44)=0,"NUEVO","ACTIVO")))) -> ACTIVO
A45: 176 | B45: RINCON TORRES JAVIER ENRIQUE | C45: 91185275 | D45: PCC | E45: XXL | F45: VESTIDOR HOMBRES | H45: =IF($B45="","",IF($B45="TRANSCARNES","ACTIVO",IF(COUNTIF(RETIROS!E:E,$B45)=1,"PENDIENTE ELIMINAR",IF(COUNTIFS(ASIGNACIONES!$D:$D,$B45,ASIGNACIONES!$I:$I,E45,ASIGNACIONES!$H:$H,$D45,ASIGNACIONES!$K:$K,$F45)=0,"NUEVO","ACTIVO")))) -> ACTIVO
A46: 177 | B46: RIVERA COLMENARES JHON NEIDER | C46: 1066093880 | D46: PCC | E46: S | F46: VESTIDOR HOMBRES | H46: =IF($B46="","",IF($B46="TRANSCARNES","ACTIVO",IF(COUNTIF(RETIROS!E:E,$B46)=1,"PENDIENTE ELIMINAR",IF(COUNTIFS(ASIGNACIONES!$D:$D,$B46,ASIGNACIONES!$I:$I,E46,ASIGNACIONES!$H:$H,$D46,ASIGNACIONES!$K:$K,$F46)=0,"NUEVO","ACTIVO")))) -> ACTIVO
A47: 18 | B47: BOTHIA RAMIREZ OMAR | C47: 13542099 | D47: PCC | E47: M | F47: VESTIDOR HOMBRES | H47: =IF($B47="","",IF($B47="TRANSCARNES","ACTIVO",IF(COUNTIF(RETIROS!E:E,$B47)=1,"PENDIENTE ELIMINAR",IF(COUNTIFS(ASIGNACIONES!$D:$D,$B47,ASIGNACIONES!$I:$I,E47,ASIGNACIONES!$H:$H,$D47,ASIGNACIONES!$K:$K,$F47)=0,"NUEVO","ACTIVO")))) -> ACTIVO
A48: 181 | B48: ROBLES BELEÑO RONALDO | C48: 1098805526 | D48: LN | E48: XL | F48: VESTIDOR HOMBRES | H48: =IF($B48="","",IF($B48="TRANSCARNES","ACTIVO",IF(COUNTIF(RETIROS!E:E,$B48)=1,"PENDIENTE ELIMINAR",IF(COUNTIFS(ASIGNACIONES!$D:$D,$B48,ASIGNACIONES!$I:$I,E48,ASIGNACIONES!$H:$H,$D48,ASIGNACIONES!$K:$K,$F48)=0,"NUEVO","ACTIVO")))) -> ACTIVO
A49: 193 | B49: ROMERO PEDRAZA SERGIO OMAR | C49: 1098738467 | D49: LN | E49: L | F49: ADMINISTRACION | H49: =IF($B49="","",IF($B49="TRANSCARNES","ACTIVO",IF(COUNTIF(RETIROS!E:E,$B49)=1,"PENDIENTE ELIMINAR",IF(COUNTIFS(ASIGNACIONES!$D:$D,$B49,ASIGNACIONES!$I:$I,E49,ASIGNACIONES!$H:$H,$D49,ASIGNACIONES!$K:$K,$F49)=0,"NUEVO","ACTIVO")))) -> ACTIVO
A50: 195 | B50: SILVA QUIJANO ANDERSON JULIAN | C50: 1005334196 | D50: PCC | E50: M | F50: VESTIDOR HOMBRES | H50: =IF($B50="","",IF($B50="TRANSCARNES","ACTIVO",IF(COUNTIF(RETIROS!E:E,$B50)=1,"PENDIENTE ELIMINAR",IF(COUNTIFS(ASIGNACIONES!$D:$D,$B50,ASIGNACIONES!$I:$I,E50,ASIGNACIONES!$H:$H,$D50,ASIGNACIONES!$K:$K,$F50)=0,"NUEVO","ACTIVO")))) -> ACTIVO
A51: 198 | B51: TRANSCARNES | C51: N/A | D51: EXT | E51: N/A | F51: VESTIDOR HOMBRES | H51: =IF($B51="","",IF($B51="TRANSCARNES","ACTIVO",IF(COUNTIF(RETIROS!E:E,$B51)=1,"PENDIENTE ELIMINAR",IF(COUNTIFS(ASIGNACIONES!$D:$D,$B51,ASIGNACIONES!$I:$I,E51,ASIGNACIONES!$H:$H,$D51,ASIGNACIONES!$K:$K,$F51)=0,"NUEVO","ACTIVO")))) -> ACTIVO
A52: 199 | B52: CARDENAS CAICEDO URIEL | C52: 13748778 | D52: LN | E52: M | F52: VESTIDOR HOMBRES | H52: =IF($B52="","",IF($B52="TRANSCARNES","ACTIVO",IF(COUNTIF(RETIROS!E:E,$B52)=1,"PENDIENTE ELIMINAR",IF(COUNTIFS(ASIGNACIONES!$D:$D,$B52,ASIGNACIONES!$I:$I,E52,ASIGNACIONES!$H:$H,$D52,ASIGNACIONES!$K:$K,$F52)=0,"NUEVO","ACTIVO")))) -> ACTIVO
A53: 1eaddc53 | B53: PADILLA BRIEVA MILEXANDE | C53: 1042436560 | D53: LN | E53: M | F53: VESTIDOR HOMBRES | H53: =IF($B53="","",IF($B53="TRANSCARNES","ACTIVO",IF(COUNTIF(RETIROS!E:E,$B53)=1,"PENDIENTE ELIMINAR",IF(COUNTIFS(ASIGNACIONES!$D:$D,$B53,ASIGNACIONES!$I:$I,E53,ASIGNACIONES!$H:$H,$D53,ASIGNACIONES!$K:$K,$F53)=0,"NUEVO","ACTIVO")))) -> ACTIVO
A54: 1f3776b4 | B54: BALLESTEROS NUÑEZ DERSO | C54: 1092671213 | D54: LN | E54: M | F54: VESTIDOR HOMBRES | H54: =IF($B54="","",IF($B54="TRANSCARNES","ACTIVO",IF(COUNTIF(RETIROS!E:E,$B54)=1,"PENDIENTE ELIMINAR",IF(COUNTIFS(ASIGNACIONES!$D:$D,$B54,ASIGNACIONES!$I:$I,E54,ASIGNACIONES!$H:$H,$D54,ASIGNACIONES!$K:$K,$F54)=0,"NUEVO","ACTIVO")))) -> ACTIVO
A55: 1f79e196 | B55: RINCÓN DIAZ MILKIN YESID | C55: 1005449415 | D55: LOG | E55: L | F55: VESTIDOR HOMBRES | H55: =IF($B55="","",IF($B55="TRANSCARNES","ACTIVO",IF(COUNTIF(RETIROS!E:E,$B55)=1,"PENDIENTE ELIMINAR",IF(COUNTIFS(ASIGNACIONES!$D:$D,$B55,ASIGNACIONES!$I:$I,E55,ASIGNACIONES!$H:$H,$D55,ASIGNACIONES!$K:$K,$F55)=0,"NUEVO","ACTIVO")))) -> ACTIVO
...

Sheet OPERARIOS
A1: id | B1: operarios nuevo
A2: =IFERROR(__xludf.DUMMYFUNCTION("FILTER(PERSONAL!$C:$C,PERSONAL!$H:$H=""NUEVO"")"),"#N/A") -> #N/A | B2: =IFERROR(__xludf.DUMMYFUNCTION("FILTER(PERSONAL!$B:$B,PERSONAL!$H:$H=""NUEVO"")"),"#N/A") -> #N/A

Sheet DOTACIONES
A1: Cantidad | B1: Codigo de Dotacion | C1: Area de USO | D1: Talla | E1: ESTADO
A2: 3 | B2: 001 | C2: PROCESO | D2: M | E2: =IF(B2="","",IF(A2=0,"NO HAY ESE CODIGO",IF(COUNTIF(ASIGNACIONES!$B$3:$B948,B2)=1,"DOTACION ASIGNADA",IF(C2="VISITAS","DOTACION VISITA",IF(C2="MTTO","DOTACION MTTO",IF(C2="PLANTA EMERGENCIA","DOTACION RES DE EMERGENCIA",IF(C2="EXTERNOS","DOTACION DE EXTERNO","DOTACION DISPONIBLE"))))))) -> DOTACION ASIGNADA
A3: 3 | B3: 002 | C3: PROCESO | D3: M | E3: =IF(B3="","",IF(A3=0,"NO HAY ESE CODIGO",IF(COUNTIF(ASIGNACIONES!$B$3:$B948,B3)=1,"DOTACION ASIGNADA",IF(C3="VISITAS","DOTACION VISITA",IF(C3="MTTO","DOTACION MTTO",IF(C3="PLANTA EMERGENCIA","DOTACION RES DE EMERGENCIA",IF(C3="EXTERNOS","DOTACION DE EXTERNO","DOTACION DISPONIBLE"))))))) -> DOTACION ASIGNADA
A4: 3 | B4: 003 | C4: PROCESO | D4: S | E4: =IF(B4="","",IF(A4=0,"NO HAY ESE CODIGO",IF(COUNTIF(ASIGNACIONES!$B$3:$B948,B4)=1,"DOTACION ASIGNADA",IF(C4="VISITAS","DOTACION VISITA",IF(C4="MTTO","DOTACION MTTO",IF(C4="PLANTA EMERGENCIA","DOTACION RES DE EMERGENCIA",IF(C4="EXTERNOS","DOTACION DE EXTERNO","DOTACION DISPONIBLE"))))))) -> DOTACION ASIGNADA
A5: 3 | B5: 004 | C5: PROCESO | D5: L | E5: =IF(B5="","",IF(A5=0,"NO HAY ESE CODIGO",IF(COUNTIF(ASIGNACIONES!$B$3:$B948,B5)=1,"DOTACION ASIGNADA",IF(C5="VISITAS","DOTACION VISITA",IF(C5="MTTO","DOTACION MTTO",IF(C5="PLANTA EMERGENCIA","DOTACION RES DE EMERGENCIA",IF(C5="EXTERNOS","DOTACION DE EXTERNO","DOTACION DISPONIBLE"))))))) -> DOTACION ASIGNADA
A6: 3 | B6: 005 | C6: PROCESO | D6: M | E6: =IF(B6="","",IF(A6=0,"NO HAY ESE CODIGO",IF(COUNTIF(ASIGNACIONES!$B$3:$B948,B6)=1,"DOTACION ASIGNADA",IF(C6="VISITAS","DOTACION VISITA",IF(C6="MTTO","DOTACION MTTO",IF(C6="PLANTA EMERGENCIA","DOTACION RES DE EMERGENCIA",IF(C6="EXTERNOS","DOTACION DE EXTERNO","DOTACION DISPONIBLE"))))))) -> DOTACION ASIGNADA
A7: 3 | B7: 006 | C7: PROCESO | D7: M | E7: =IF(B7="","",IF(A7=0,"NO HAY ESE CODIGO",IF(COUNTIF(ASIGNACIONES!$B$3:$B948,B7)=1,"DOTACION ASIGNADA",IF(C7="VISITAS","DOTACION VISITA",IF(C7="MTTO","DOTACION MTTO",IF(C7="PLANTA EMERGENCIA","DOTACION RES DE EMERGENCIA",IF(C7="EXTERNOS","DOTACION DE EXTERNO","DOTACION DISPONIBLE"))))))) -> DOTACION ASIGNADA
A8: 3 | B8: 007 | C8: PROCESO | D8: S | E8: =IF(B8="","",IF(A8=0,"NO HAY ESE CODIGO",IF(COUNTIF(ASIGNACIONES!$B$3:$B948,B8)=1,"DOTACION ASIGNADA",IF(C8="VISITAS","DOTACION VISITA",IF(C8="MTTO","DOTACION MTTO",IF(C8="PLANTA EMERGENCIA","DOTACION RES DE EMERGENCIA",IF(C8="EXTERNOS","DOTACION DE EXTERNO","DOTACION DISPONIBLE"))))))) -> DOTACION ASIGNADA
A9: 3 | B9: 008 | C9: PROCESO | D9: L | E9: =IF(B9="","",IF(A9=0,"NO HAY ESE CODIGO",IF(COUNTIF(ASIGNACIONES!$B$3:$B948,B9)=1,"DOTACION ASIGNADA",IF(C9="VISITAS","DOTACION VISITA",IF(C9="MTTO","DOTACION MTTO",IF(C9="PLANTA EMERGENCIA","DOTACION RES DE EMERGENCIA",IF(C9="EXTERNOS","DOTACION DE EXTERNO","DOTACION DISPONIBLE"))))))) -> DOTACION ASIGNADA
A10: 3 | B10: 009 | C10: PROCESO | D10: L | E10: =IF(B10="","",IF(A10=0,"NO HAY ESE CODIGO",IF(COUNTIF(ASIGNACIONES!$B$3:$B948,B10)=1,"DOTACION ASIGNADA",IF(C10="VISITAS","DOTACION VISITA",IF(C10="MTTO","DOTACION MTTO",IF(C10="PLANTA EMERGENCIA","DOTACION RES DE EMERGENCIA",IF(C10="EXTERNOS","DOTACION DE EXTERNO","DOTACION DISPONIBLE"))))))) -> DOTACION ASIGNADA
A11: 2 | B11: 010 | C11: PROCESO | D11: M | E11: =IF(B11="","",IF(A11=0,"NO HAY ESE CODIGO",IF(COUNTIF(ASIGNACIONES!$B$3:$B948,B11)=1,"DOTACION ASIGNADA",IF(C11="VISITAS","DOTACION VISITA",IF(C11="MTTO","DOTACION MTTO",IF(C11="PLANTA EMERGENCIA","DOTACION RES DE EMERGENCIA",IF(C11="EXTERNOS","DOTACION DE EXTERNO","DOTACION DISPONIBLE"))))))) -> DOTACION DISPONIBLE
A12: 3 | B12: 011 | C12: PROCESO | D12: S | E12: =IF(B12="","",IF(A12=0,"NO HAY ESE CODIGO",IF(COUNTIF(ASIGNACIONES!$B$3:$B948,B12)=1,"DOTACION ASIGNADA",IF(C12="VISITAS","DOTACION VISITA",IF(C12="MTTO","DOTACION MTTO",IF(C12="PLANTA EMERGENCIA","DOTACION RES DE EMERGENCIA",IF(C12="EXTERNOS","DOTACION DE EXTERNO","DOTACION DISPONIBLE"))))))) -> DOTACION ASIGNADA
A13: 3 | B13: 012 | C13: PROCESO | D13: M | E13: =IF(B13="","",IF(A13=0,"NO HAY ESE CODIGO",IF(COUNTIF(ASIGNACIONES!$B$3:$B948,B13)=1,"DOTACION ASIGNADA",IF(C13="VISITAS","DOTACION VISITA",IF(C13="MTTO","DOTACION MTTO",IF(C13="PLANTA EMERGENCIA","DOTACION RES DE EMERGENCIA",IF(C13="EXTERNOS","DOTACION DE EXTERNO","DOTACION DISPONIBLE"))))))) -> DOTACION ASIGNADA
A14: 3 | B14: 013 | C14: PROCESO | D14: L | E14: =IF(B14="","",IF(A14=0,"NO HAY ESE CODIGO",IF(COUNTIF(ASIGNACIONES!$B$3:$B948,B14)=1,"DOTACION ASIGNADA",IF(C14="VISITAS","DOTACION VISITA",IF(C14="MTTO","DOTACION MTTO",IF(C14="PLANTA EMERGENCIA","DOTACION RES DE EMERGENCIA",IF(C14="EXTERNOS","DOTACION DE EXTERNO","DOTACION DISPONIBLE"))))))) -> DOTACION ASIGNADA
A15: 3 | B15: 014 | C15: PROCESO | D15: L | E15: =IF(B15="","",IF(A15=0,"NO HAY ESE CODIGO",IF(COUNTIF(ASIGNACIONES!$B$3:$B948,B15)=1,"DOTACION ASIGNADA",IF(C15="VISITAS","DOTACION VISITA",IF(C15="MTTO","DOTACION MTTO",IF(C15="PLANTA EMERGENCIA","DOTACION RES DE EMERGENCIA",IF(C15="EXTERNOS","DOTACION DE EXTERNO","DOTACION DISPONIBLE"))))))) -> DOTACION DISPONIBLE
A16: 3 | B16: 015 | C16: PROCESO | D16: M | E16: =IF(B16="","",IF(A16=0,"NO HAY ESE CODIGO",IF(COUNTIF(ASIGNACIONES!$B$3:$B948,B16)=1,"DOTACION ASIGNADA",IF(C16="VISITAS","DOTACION VISITA",IF(C16="MTTO","DOTACION MTTO",IF(C16="PLANTA EMERGENCIA","DOTACION RES DE EMERGENCIA",IF(C16="EXTERNOS","DOTACION DE EXTERNO","DOTACION DISPONIBLE"))))))) -> DOTACION ASIGNADA
A17: 3 | B17: 016 | C17: PROCESO | D17: M | E17: =IF(B17="","",IF(A17=0,"NO HAY ESE CODIGO",IF(COUNTIF(ASIGNACIONES!$B$3:$B948,B17)=1,"DOTACION ASIGNADA",IF(C17="VISITAS","DOTACION VISITA",IF(C17="MTTO","DOTACION MTTO",IF(C17="PLANTA EMERGENCIA","DOTACION RES DE EMERGENCIA",IF(C17="EXTERNOS","DOTACION DE EXTERNO","DOTACION DISPONIBLE"))))))) -> DOTACION ASIGNADA
A18: 3 | B18: 017 | C18: PROCESO | D18: S | E18: =IF(B18="","",IF(A18=0,"NO HAY ESE CODIGO",IF(COUNTIF(ASIGNACIONES!$B$3:$B948,B18)=1,"DOTACION ASIGNADA",IF(C18="VISITAS","DOTACION VISITA",IF(C18="MTTO","DOTACION MTTO",IF(C18="PLANTA EMERGENCIA","DOTACION RES DE EMERGENCIA",IF(C18="EXTERNOS","DOTACION DE EXTERNO","DOTACION DISPONIBLE"))))))) -> DOTACION ASIGNADA
A19: 2 | B19: 018 | C19: PROCESO | D19: XL | E19: =IF(B19="","",IF(A19=0,"NO HAY ESE CODIGO",IF(COUNTIF(ASIGNACIONES!$B$3:$B948,B19)=1,"DOTACION ASIGNADA",IF(C19="VISITAS","DOTACION VISITA",IF(C19="MTTO","DOTACION MTTO",IF(C19="PLANTA EMERGENCIA","DOTACION RES DE EMERGENCIA",IF(C19="EXTERNOS","DOTACION DE EXTERNO","DOTACION DISPONIBLE"))))))) -> DOTACION ASIGNADA
A20: 3 | B20: 019 | C20: PROCESO | D20: XL | E20: =IF(B20="","",IF(A20=0,"NO HAY ESE CODIGO",IF(COUNTIF(ASIGNACIONES!$B$3:$B948,B20)=1,"DOTACION ASIGNADA",IF(C20="VISITAS","DOTACION VISITA",IF(C20="MTTO","DOTACION MTTO",IF(C20="PLANTA EMERGENCIA","DOTACION RES DE EMERGENCIA",IF(C20="EXTERNOS","DOTACION DE EXTERNO","DOTACION DISPONIBLE"))))))) -> DOTACION ASIGNADA
A21: 3 | B21: 020 | C21: PROCESO | D21: L | E21: =IF(B21="","",IF(A21=0,"NO HAY ESE CODIGO",IF(COUNTIF(ASIGNACIONES!$B$3:$B948,B21)=1,"DOTACION ASIGNADA",IF(C21="VISITAS","DOTACION VISITA",IF(C21="MTTO","DOTACION MTTO",IF(C21="PLANTA EMERGENCIA","DOTACION RES DE EMERGENCIA",IF(C21="EXTERNOS","DOTACION DE EXTERNO","DOTACION DISPONIBLE"))))))) -> DOTACION ASIGNADA
A22: 3 | B22: 021 | C22: PROCESO | D22: XXL | E22: =IF(B22="","",IF(A22=0,"NO HAY ESE CODIGO",IF(COUNTIF(ASIGNACIONES!$B$3:$B948,B22)=1,"DOTACION ASIGNADA",IF(C22="VISITAS","DOTACION VISITA",IF(C22="MTTO","DOTACION MTTO",IF(C22="PLANTA EMERGENCIA","DOTACION RES DE EMERGENCIA",IF(C22="EXTERNOS","DOTACION DE EXTERNO","DOTACION DISPONIBLE"))))))) -> DOTACION ASIGNADA
A23: 3 | B23: 022 | C23: PROCESO | D23: S | E23: =IF(B23="","",IF(A23=0,"NO HAY ESE CODIGO",IF(COUNTIF(ASIGNACIONES!$B$3:$B948,B23)=1,"DOTACION ASIGNADA",IF(C23="VISITAS","DOTACION VISITA",IF(C23="MTTO","DOTACION MTTO",IF(C23="PLANTA EMERGENCIA","DOTACION RES DE EMERGENCIA",IF(C23="EXTERNOS","DOTACION DE EXTERNO","DOTACION DISPONIBLE"))))))) -> DOTACION ASIGNADA
A24: 3 | B24: 023 | C24: PROCESO | D24: S | E24: =IF(B24="","",IF(A24=0,"NO HAY ESE CODIGO",IF(COUNTIF(ASIGNACIONES!$B$3:$B948,B24)=1,"DOTACION ASIGNADA",IF(C24="VISITAS","DOTACION VISITA",IF(C24="MTTO","DOTACION MTTO",IF(C24="PLANTA EMERGENCIA","DOTACION RES DE EMERGENCIA",IF(C24="EXTERNOS","DOTACION DE EXTERNO","DOTACION DISPONIBLE"))))))) -> DOTACION ASIGNADA
A25: 1 | B25: 024 | C25: PROCESO | D25: XL | E25: =IF(B25="","",IF(A25=0,"NO HAY ESE CODIGO",IF(COUNTIF(ASIGNACIONES!$B$3:$B948,B25)=1,"DOTACION ASIGNADA",IF(C25="VISITAS","DOTACION VISITA",IF(C25="MTTO","DOTACION MTTO",IF(C25="PLANTA EMERGENCIA","DOTACION RES DE EMERGENCIA",IF(C25="EXTERNOS","DOTACION DE EXTERNO","DOTACION DISPONIBLE"))))))) -> DOTACION ASIGNADA
A26: 3 | B26: 025 | C26: PROCESO | D26: M | E26: =IF(B26="","",IF(A26=0,"NO HAY ESE CODIGO",IF(COUNTIF(ASIGNACIONES!$B$3:$B948,B26)=1,"DOTACION ASIGNADA",IF(C26="VISITAS","DOTACION VISITA",IF(C26="MTTO","DOTACION MTTO",IF(C26="PLANTA EMERGENCIA","DOTACION RES DE EMERGENCIA",IF(C26="EXTERNOS","DOTACION DE EXTERNO","DOTACION DISPONIBLE"))))))) -> DOTACION ASIGNADA
A27: 3 | B27: 026 | C27: PROCESO | D27: L | E27: =IF(B27="","",IF(A27=0,"NO HAY ESE CODIGO",IF(COUNTIF(ASIGNACIONES!$B$3:$B948,B27)=1,"DOTACION ASIGNADA",IF(C27="VISITAS","DOTACION VISITA",IF(C27="MTTO","DOTACION MTTO",IF(C27="PLANTA EMERGENCIA","DOTACION RES DE EMERGENCIA",IF(C27="EXTERNOS","DOTACION DE EXTERNO","DOTACION DISPONIBLE"))))))) -> DOTACION DISPONIBLE
A28: 3 | B28: 027 | C28: PROCESO | D28: L | E28: =IF(B28="","",IF(A28=0,"NO HAY ESE CODIGO",IF(COUNTIF(ASIGNACIONES!$B$3:$B948,B28)=1,"DOTACION ASIGNADA",IF(C28="VISITAS","DOTACION VISITA",IF(C28="MTTO","DOTACION MTTO",IF(C28="PLANTA EMERGENCIA","DOTACION RES DE EMERGENCIA",IF(C28="EXTERNOS","DOTACION DE EXTERNO","DOTACION DISPONIBLE"))))))) -> DOTACION ASIGNADA
A29: 3 | B29: 028 | C29: PROCESO | D29: M | E29: =IF(B29="","",IF(A29=0,"NO HAY ESE CODIGO",IF(COUNTIF(ASIGNACIONES!$B$3:$B948,B29)=1,"DOTACION ASIGNADA",IF(C29="VISITAS","DOTACION VISITA",IF(C29="MTTO","DOTACION MTTO",IF(C29="PLANTA EMERGENCIA","DOTACION RES DE EMERGENCIA",IF(C29="EXTERNOS","DOTACION DE EXTERNO","DOTACION DISPONIBLE"))))))) -> DOTACION ASIGNADA
A30: 3 | B30: 029 | C30: PROCESO | D30: S | E30: =IF(B30="","",IF(A30=0,"NO HAY ESE CODIGO",IF(COUNTIF(ASIGNACIONES!$B$3:$B948,B30)=1,"DOTACION ASIGNADA",IF(C30="VISITAS","DOTACION VISITA",IF(C30="MTTO","DOTACION MTTO",IF(C30="PLANTA EMERGENCIA","DOTACION RES DE EMERGENCIA",IF(C30="EXTERNOS","DOTACION DE EXTERNO","DOTACION DISPONIBLE"))))))) -> DOTACION ASIGNADA
A31: 3 | B31: 030 | C31: PROCESO | D31: S | E31: =IF(B31="","",IF(A31=0,"NO HAY ESE CODIGO",IF(COUNTIF(ASIGNACIONES!$B$3:$B948,B31)=1,"DOTACION ASIGNADA",IF(C31="VISITAS","DOTACION VISITA",IF(C31="MTTO","DOTACION MTTO",IF(C31="PLANTA EMERGENCIA","DOTACION RES DE EMERGENCIA",IF(C31="EXTERNOS","DOTACION DE EXTERNO","DOTACION DISPONIBLE"))))))) -> DOTACION ASIGNADA
A32: 3 | B32: 031 | C32: PROCESO | D32: M | E32: =IF(B32="","",IF(A32=0,"NO HAY ESE CODIGO",IF(COUNTIF(ASIGNACIONES!$B$3:$B948,B32)=1,"DOTACION ASIGNADA",IF(C32="VISITAS","DOTACION VISITA",IF(C32="MTTO","DOTACION MTTO",IF(C32="PLANTA EMERGENCIA","DOTACION RES DE EMERGENCIA",IF(C32="EXTERNOS","DOTACION DE EXTERNO","DOTACION DISPONIBLE"))))))) -> DOTACION ASIGNADA
A33: 2 | B33: 032 | C33: PROCESO | D33: L | E33: =IF(B33="","",IF(A33=0,"NO HAY ESE CODIGO",IF(COUNTIF(ASIGNACIONES!$B$3:$B948,B33)=1,"DOTACION ASIGNADA",IF(C33="VISITAS","DOTACION VISITA",IF(C33="MTTO","DOTACION MTTO",IF(C33="PLANTA EMERGENCIA","DOTACION RES DE EMERGENCIA",IF(C33="EXTERNOS","DOTACION DE EXTERNO","DOTACION DISPONIBLE"))))))) -> DOTACION ASIGNADA
A34: 3 | B34: 033 | C34: PROCESO | D34: M | E34: =IF(B34="","",IF(A34=0,"NO HAY ESE CODIGO",IF(COUNTIF(ASIGNACIONES!$B$3:$B948,B34)=1,"DOTACION ASIGNADA",IF(C34="VISITAS","DOTACION VISITA",IF(C34="MTTO","DOTACION MTTO",IF(C34="PLANTA EMERGENCIA","DOTACION RES DE EMERGENCIA",IF(C34="EXTERNOS","DOTACION DE EXTERNO","DOTACION DISPONIBLE"))))))) -> DOTACION ASIGNADA
